Workbook

Sheet 1 в день
A2: 7 | E2: =IF(AJ2=0,0,(E12*AJ12 + E21*AJ21 + E30*AJ30 + E39*AJ39 + E48*AJ48 + E57*AJ57 ) /AJ2 ) -> 0.94116611 | F2: Микроцикл | N2: 1 | AE2: =AE12+AE21+AE30+AE39+AE48+AE57 -> 15812.5 | AF2: =IFERROR(AE2/AJ2,0) -> 52.533223 | AG2: =IF(AJ2=0,0,(AG12*AJ12 + AG21*AJ21 + AG30*AJ30 + AG39*AJ39 + AG48*AJ48 + AG57*AJ57 ) /AJ2 ) -> 0.54341556 | AI2: =AI12+AI21+AI30+AI39+AI48+AI57 -> 15041.925 | AJ2: =AJ12+AJ21+AJ30+AJ39+AJ48+AJ57 -> 301 | AK2: =AK12+AK21+AK30+AK39+AK48+AK57 -> 0.25694444
A3: Дата | B3: Нагрузка | C3: Группа | D3: Упражнения | E3: Коэф | F3: Множ | G3: Вес | H3: Пов | I3: Под | J3: % | K3: Вес | L3: Пов | M3: Под | N3: % | O3: Вес | P3: Пов | Q3: Под | R3: % | S3: Вес | T3: Пов | U3: Под | V3: % | W3: Вес | X3: Пов | Y3: Под | Z3: % | AA3: Вес | AB3: Пов | AC3: Под | AD3: % | AE3: Тоннаж | AF3: Ср.вес | AG3: ОИ | AH3: ПМ | AI3: Инт.Ф+Б | AJ3: КПШ | AK3: Время | AL3: Комментарии
A4: =A5 -> 43780 | B4: Тяжелая | C4: ПР | D4: Присед | E4: 1.2 | G4: =IF(J4<>0, IFERROR(IF( $F4=2, MROUND($AH4*J4,1), IF( OR($F4="",$F4=1), MROUND($AH4*J4,2.5), MROUND($AH4*J4, 0.1))), "" ), "") -> 77.5 | H4: 4 | I4: 1 | J4: 0.57 | K4: =IF(N4<>0, IFERROR(IF( $F4=2, MROUND($AH4*N4,1), IF( OR($F4="",$F4=1), MROUND($AH4*N4,2.5), MROUND($AH4*N4, 0.1))), "" ), "") -> 87.5 | L4: 3 | M4: 3 | N4: 0.65 | O4: =IF(R4<>0, IFERROR(IF( $F4=2, MROUND($AH4*R4,1), IF( OR($F4="",$F4=1), MROUND($AH4*R4,2.5), MROUND($AH4*R4, 0.1))), "" ), "") -> 102.5 | P4: 2 | Q4: 3 | R4: 0.75 | S4: =IF(V4<>0, IFERROR(IF( $F4=2, MROUND($AH4*V4,1), IF( OR($F4="",$F4=1), MROUND($AH4*V4,2.5), MROUND($AH4*V4, 0.1))), "" ), "") | W4: =IF(Z4<>0, IFERROR(IF( $F4=2, MROUND($AH4*Z4,1), IF( OR($F4="",$F4=1), MROUND($AH4*Z4,2.5), MROUND($AH4*Z4, 0.1))), "" ), "") | AA4: =IF(AD4<>0, IFERROR(IF( $F4=2, MROUND($AH4*AD4,1), IF( OR($F4="",$F4=1), MROUND($AH4*AD4,2.5), MROUND($AH4*AD4, 0.1))), "" ), "") | AE4: =(IF(ISNUMBER(G4),G4,0)*H4*I4+IF(ISNUMBER(K4),K4,1)*L4*M4+IF(ISNUMBER(O4),O4,1)*P4*Q4+IF(ISNUMBER(S4),S4,1)*T4*U4+IF(ISNUMBER(W4),W4,1)*X4*Y4+IF(ISNUMBER(AA4),AA4,1)*AB4*AC4)*IF(ISNUMBER(F4),F4,1) -> 1712.5 | AF4: =IFERROR(AE4/AJ4,0) -> 90.131579 | AG4: =IFERROR((AF4/(AH4*IF(ISNUMBER(F4),F4,1))),0) -> 0.66764133 | AH4: 135 | AI4: =( IF(ISNUMBER(G4), VLOOKUP(G4/$AH4,F!$A1:$B101,2,1)*G4*$H4*$I4,0)+IF(ISNUMBER(K4), VLOOKUP(K4/$AH4,F!$A1:$B101,2,1)*K4*$L4*$M4,0)+IF(ISNUMBER(O4), VLOOKUP(O4/$AH4,F!$A1:$B101,2,1)*O4*$P4*$Q4,0)+IF(ISNUMBER(S4), VLOOKUP(S4/$AH4,F!$A1:$B101,2,1)*S4*$T4*$U4,0)+IF(ISNUMBER(W4), VLOOKUP(W4/$AH4,F!$A1:$B101,2,1)*W4*$X4*$Y4,0)+IF(ISNUMBER(AA4), VLOOKUP(AA4/$AH4,F!$A1:$B101,2,1)*AA4*$AB4*$AC4,0))*IF(ISNUMBER(F4),F4,1)*IF(ISNUMBER(E4),E4,1) -> 1853.34 | AJ4: =H4*I4+L4*M4+P4*Q4+T4*U4+X4*Y4+AB4*AC4 -> 19 | AK4: {=IFERROR(I4*INDEX(F!$P$21:$AB$33, MATCH(G4/$AH4, F!$O$21:$O$33,1), MATCH(E4, F!$P$20:$AB$20,1)), 0 ) +IFERROR( M4*INDEX(F!$P$21:$AB$33, MATCH(K4/$AH4, F!$O$21:$O$33,1), MATCH(E4, F!$P$20:$AB$20,1)),0) + IFERROR( Q4*INDEX(F!$P$21:$AB$33, MATCH(O4/$AH4, F!$O$21:$O$33,1), MATCH(E4, F!$P$20:$AB$20,1)), 0) + IFERROR( U4*INDEX(F!$P$21:$AB$33, MATCH(S4/$AH4, F!$O$21:$O$33,1), MATCH(E4, F!$P$20:$AB$20,1)),0) + IFERROR(Y4*INDEX(F!$P$21:$AB$33, MATCH(W4/$AH4, F!$O$21:$O$33,1), MATCH(E4, F!$P$20:$AB$20,1)),0) + IFERROR( AC4*INDEX(F!$P$21:$AB$33, MATCH(AA4/$AH4, F!$O$21:$O$33,1), MATCH(E4, F!$P$20:$AB$20,1)),)} -> 31
A5: 43780 | B5: Тяжелая | C5: ЖМ | D5: Жим лежа | E5: 1 | G5: =IF(J5<>0, IFERROR(IF( $F5=2, MROUND($AH5*J5,1), IF( OR($F5="",$F5=1), MROUND($AH5*J5,2.5), MROUND($AH5*J5, 0.1))), "" ), "") -> 57.5 | H5: 3 | I5: 1 | J5: 0.6 | K5: =IF(N5<>0, IFERROR(IF( $F5=2, MROUND($AH5*N5,1), IF( OR($F5="",$F5=1), MROUND($AH5*N5,2.5), MROUND($AH5*N5, 0.1))), "" ), "") -> 67.5 | L5: 2 | M5: 2 | N5: 0.7 | O5: =IF(R5<>0, IFERROR(IF( $F5=2, MROUND($AH5*R5,1), IF( OR($F5="",$F5=1), MROUND($AH5*R5,2.5), MROUND($AH5*R5, 0.1))), "" ), "") -> 75 | P5: 1 | Q5: 2 | R5: 0.78 | S5: =IF(V5<>0, IFERROR(IF( $F5=2, MROUND($AH5*V5,1), IF( OR($F5="",$F5=1), MROUND($AH5*V5,2.5), MROUND($AH5*V5, 0.1))), "" ), "") | W5: =IF(Z5<>0, IFERROR(IF( $F5=2, MROUND($AH5*Z5,1), IF( OR($F5="",$F5=1), MROUND($AH5*Z5,2.5), MROUND($AH5*Z5, 0.1))), "" ), "") | AA5: =IF(AD5<>0, IFERROR(IF( $F5=2, MROUND($AH5*AD5,1), IF( OR($F5="",$F5=1), MROUND($AH5*AD5,2.5), MROUND($AH5*AD5, 0.1))), "" ), "") | AE5: =(IF(ISNUMBER(G5),G5,0)*H5*I5+IF(ISNUMBER(K5),K5,1)*L5*M5+IF(ISNUMBER(O5),O5,1)*P5*Q5+IF(ISNUMBER(S5),S5,1)*T5*U5+IF(ISNUMBER(W5),W5,1)*X5*Y5+IF(ISNUMBER(AA5),AA5,1)*AB5*AC5)*IF(ISNUMBER(F5),F5,1) -> 592.5 | AF5: =IFERROR(AE5/AJ5,0) -> 65.833333 | AG5: =IFERROR((AF5/(AH5*IF(ISNUMBER(F5),F5,1))),0) -> 0.69298246 | AH5: 95 | AI5: =( IF(ISNUMBER(G5), VLOOKUP(G5/$AH5,F!$A1:$B101,2,1)*G5*$H5*$I5,0)+IF(ISNUMBER(K5), VLOOKUP(K5/$AH5,F!$A1:$B101,2,1)*K5*$L5*$M5,0)+IF(ISNUMBER(O5), VLOOKUP(O5/$AH5,F!$A1:$B101,2,1)*O5*$P5*$Q5,0)+IF(ISNUMBER(S5), VLOOKUP(S5/$AH5,F!$A1:$B101,2,1)*S5*$T5*$U5,0)+IF(ISNUMBER(W5), VLOOKUP(W5/$AH5,F!$A1:$B101,2,1)*W5*$X5*$Y5,0)+IF(ISNUMBER(AA5), VLOOKUP(AA5/$AH5,F!$A1:$B101,2,1)*AA5*$AB5*$AC5,0))*IF(ISNUMBER(F5),F5,1)*IF(ISNUMBER(E5),E5,1) -> 587.25 | AJ5: =H5*I5+L5*M5+P5*Q5+T5*U5+X5*Y5+AB5*AC5 -> 9 | AK5: {=IFERROR(I5*INDEX(F!$P$21:$AB$33, MATCH(G5/$AH5, F!$O$21:$O$33,1), MATCH(E5, F!$P$20:$AB$20,1)), 0 ) +IFERROR( M5*INDEX(F!$P$21:$AB$33, MATCH(K5/$AH5, F!$O$21:$O$33,1), MATCH(E5, F!$P$20:$AB$20,1)),0) + IFERROR( Q5*INDEX(F!$P$21:$AB$33, MATCH(O5/$AH5, F!$O$21:$O$33,1), MATCH(E5, F!$P$20:$AB$20,1)), 0) + IFERROR( U5*INDEX(F!$P$21:$AB$33, MATCH(S5/$AH5, F!$O$21:$O$33,1), MATCH(E5, F!$P$20:$AB$20,1)),0) + IFERROR(Y5*INDEX(F!$P$21:$AB$33, MATCH(W5/$AH5, F!$O$21:$O$33,1), MATCH(E5, F!$P$20:$AB$20,1)),0) + IFERROR( AC5*INDEX(F!$P$21:$AB$33, MATCH(AA5/$AH5, F!$O$21:$O$33,1), MATCH(E5, F!$P$20:$AB$20,1)),)} -> 19
B6: Тяжелая | C6: ПР | D6: Присед | E6: 1.2 | G6: =IF(J6<>0, IFERROR(IF( $F6=2, MROUND($AH6*J6,1), IF( OR($F6="",$F6=1), MROUND($AH6*J6,2.5), MROUND($AH6*J6, 0.1))), "" ), "") -> 80 | H6: 4 | I6: 1 | J6: 0.6 | K6: =IF(N6<>0, IFERROR(IF( $F6=2, MROUND($AH6*N6,1), IF( OR($F6="",$F6=1), MROUND($AH6*N6,2.5), MROUND($AH6*N6, 0.1))), "" ), "") -> 95 | L6: 4 | M6: 4 | N6: 0.7 | O6: =IF(R6<>0, IFERROR(IF( $F6=2, MROUND($AH6*R6,1), IF( OR($F6="",$F6=1), MROUND($AH6*R6,2.5), MROUND($AH6*R6, 0.1))), "" ), "") | S6: =IF(V6<>0, IFERROR(IF( $F6=2, MROUND($AH6*V6,1), IF( OR($F6="",$F6=1), MROUND($AH6*V6,2.5), MROUND($AH6*V6, 0.1))), "" ), "") | W6: =IF(Z6<>0, IFERROR(IF( $F6=2, MROUND($AH6*Z6,1), IF( OR($F6="",$F6=1), MROUND($AH6*Z6,2.5), MROUND($AH6*Z6, 0.1))), "" ), "") | AA6: =IF(AD6<>0, IFERROR(IF( $F6=2, MROUND($AH6*AD6,1), IF( OR($F6="",$F6=1), MROUND($AH6*AD6,2.5), MROUND($AH6*AD6, 0.1))), "" ), "") | AE6: =(IF(ISNUMBER(G6),G6,0)*H6*I6+IF(ISNUMBER(K6),K6,1)*L6*M6+IF(ISNUMBER(O6),O6,1)*P6*Q6+IF(ISNUMBER(S6),S6,1)*T6*U6+IF(ISNUMBER(W6),W6,1)*X6*Y6+IF(ISNUMBER(AA6),AA6,1)*AB6*AC6)*IF(ISNUMBER(F6),F6,1) -> 1840 | AF6: =IFERROR(AE6/AJ6,0) -> 92 | AG6: =IFERROR((AF6/(AH6*IF(ISNUMBER(F6),F6,1))),0) -> 0.68148148 | AH6: =AH4 -> 135 | AI6: =( IF(ISNUMBER(G6), VLOOKUP(G6/$AH6,F!$A1:$B101,2,1)*G6*$H6*$I6,0)+IF(ISNUMBER(K6), VLOOKUP(K6/$AH6,F!$A1:$B101,2,1)*K6*$L6*$M6,0)+IF(ISNUMBER(O6), VLOOKUP(O6/$AH6,F!$A1:$B101,2,1)*O6*$P6*$Q6,0)+IF(ISNUMBER(S6), VLOOKUP(S6/$AH6,F!$A1:$B101,2,1)*S6*$T6*$U6,0)+IF(ISNUMBER(W6), VLOOKUP(W6/$AH6,F!$A1:$B101,2,1)*W6*$X6*$Y6,0)+IF(ISNUMBER(AA6), VLOOKUP(AA6/$AH6,F!$A1:$B101,2,1)*AA6*$AB6*$AC6,0))*IF(ISNUMBER(F6),F6,1)*IF(ISNUMBER(E6),E6,1) -> 1902.72 | AJ6: =H6*I6+L6*M6+P6*Q6+T6*U6+X6*Y6+AB6*AC6 -> 20 | AK6: {=IFERROR(I6*INDEX(F!$P$21:$AB$33, MATCH(G6/$AH6, F!$O$21:$O$33,1), MATCH(E6, F!$P$20:$AB$20,1)), 0 ) +IFERROR( M6*INDEX(F!$P$21:$AB$33, MATCH(K6/$AH6, F!$O$21:$O$33,1), MATCH(E6, F!$P$20:$AB$20,1)),0) + IFERROR( Q6*INDEX(F!$P$21:$AB$33, MATCH(O6/$AH6, F!$O$21:$O$33,1), MATCH(E6, F!$P$20:$AB$20,1)), 0) + IFERROR( U6*INDEX(F!$P$21:$AB$33, MATCH(S6/$AH6, F!$O$21:$O$33,1), MATCH(E6, F!$P$20:$AB$20,1)),0) + IFERROR(Y6*INDEX(F!$P$21:$AB$33, MATCH(W6/$AH6, F!$O$21:$O$33,1), MATCH(E6, F!$P$20:$AB$20,1)),0) + IFERROR( AC6*INDEX(F!$P$21:$AB$33, MATCH(AA6/$AH6, F!$O$21:$O$33,1), MATCH(E6, F!$P$20:$AB$20,1)),)} -> 24
B7: Средняя | C7: ЖМ | D7: Жим гантелей | E7: 1 | F7: 2 | G7: =IF(J7<>0, IFERROR(IF( $F7=2, MROUND($AH7*J7,1), IF( OR($F7="",$F7=1), MROUND($AH7*J7,2.5), MROUND($AH7*J7, 0.1))), "" ), "") -> 20 | H7: 5 | I7: 5 | J7: 0.65 | K7: =IF(N7<>0, IFERROR(IF( $F7=2, MROUND($AH7*N7,1), IF( OR($F7="",$F7=1), MROUND($AH7*N7,2.5), MROUND($AH7*N7, 0.1))), "" ), "") | O7: =IF(R7<>0, IFERROR(IF( $F7=2, MROUND($AH7*R7,1), IF( OR($F7="",$F7=1), MROUND($AH7*R7,2.5), MROUND($AH7*R7, 0.1))), "" ), "") | S7: =IF(V7<>0, IFERROR(IF( $F7=2, MROUND($AH7*V7,1), IF( OR($F7="",$F7=1), MROUND($AH7*V7,2.5), MROUND($AH7*V7, 0.1))), "" ), "") | W7: =IF(Z7<>0, IFERROR(IF( $F7=2, MROUND($AH7*Z7,1), IF( OR($F7="",$F7=1), MROUND($AH7*Z7,2.5), MROUND($AH7*Z7, 0.1))), "" ), "") | AA7: =IF(AD7<>0, IFERROR(IF( $F7=2, MROUND($AH7*AD7,1), IF( OR($F7="",$F7=1), MROUND($AH7*AD7,2.5), MROUND($AH7*AD7, 0.1))), "" ), "") | AE7: =(IF(ISNUMBER(G7),G7,0)*H7*I7+IF(ISNUMBER(K7),K7,1)*L7*M7+IF(ISNUMBER(O7),O7,1)*P7*Q7+IF(ISNUMBER(S7),S7,1)*T7*U7+IF(ISNUMBER(W7),W7,1)*X7*Y7+IF(ISNUMBER(AA7),AA7,1)*AB7*AC7)*IF(ISNUMBER(F7),F7,1) -> 1000 | AF7: =IFERROR(AE7/AJ7,0) -> 40 | AG7: =IFERROR((AF7/(AH7*IF(ISNUMBER(F7),F7,1))),0) -> 0.65789474 | AH7: =AH5*0.32 -> 30.4 | AI7: =( IF(ISNUMBER(G7), VLOOKUP(G7/$AH7,F!$A1:$B101,2,1)*G7*$H7*$I7,0)+IF(ISNUMBER(K7), VLOOKUP(K7/$AH7,F!$A1:$B101,2,1)*K7*$L7*$M7,0)+IF(ISNUMBER(O7), VLOOKUP(O7/$AH7,F!$A1:$B101,2,1)*O7*$P7*$Q7,0)+IF(ISNUMBER(S7), VLOOKUP(S7/$AH7,F!$A1:$B101,2,1)*S7*$T7*$U7,0)+IF(ISNUMBER(W7), VLOOKUP(W7/$AH7,F!$A1:$B101,2,1)*W7*$X7*$Y7,0)+IF(ISNUMBER(AA7), VLOOKUP(AA7/$AH7,F!$A1:$B101,2,1)*AA7*$AB7*$AC7,0))*IF(ISNUMBER(F7),F7,1)*IF(ISNUMBER(E7),E7,1) -> 800 | AJ7: =H7*I7+L7*M7+P7*Q7+T7*U7+X7*Y7+AB7*AC7 -> 25 | AK7: {=IFERROR(I7*INDEX(F!$P$21:$AB$33, MATCH(G7/$AH7, F!$O$21:$O$33,1), MATCH(E7, F!$P$20:$AB$20,1)), 0 ) +IFERROR( M7*INDEX(F!$P$21:$AB$33, MATCH(K7/$AH7, F!$O$21:$O$33,1), MATCH(E7, F!$P$20:$AB$20,1)),0) + IFERROR( Q7*INDEX(F!$P$21:$AB$33, MATCH(O7/$AH7, F!$O$21:$O$33,1), MATCH(E7, F!$P$20:$AB$20,1)), 0) + IFERROR( U7*INDEX(F!$P$21:$AB$33, MATCH(S7/$AH7, F!$O$21:$O$33,1), MATCH(E7, F!$P$20:$AB$20,1)),0) + IFERROR(Y7*INDEX(F!$P$21:$AB$33, MATCH(W7/$AH7, F!$O$21:$O$33,1), MATCH(E7, F!$P$20:$AB$20,1)),0) + IFERROR( AC7*INDEX(F!$P$21:$AB$33, MATCH(AA7/$AH7, F!$O$21:$O$33,1), MATCH(E7, F!$P$20:$AB$20,1)),)} -> 15
B8: Легкая | C8: ОФП | D8: Французский жим | E8: 0.4 | G8: =IF(J8<>0, IFERROR(IF( $F8=2, MROUND($AH8*J8,1), IF( OR($F8="",$F8=1), MROUND($AH8*J8,2.5), MROUND($AH8*J8, 0.1))), "" ), "") -> 20 | H8: 5 | I8: 5 | J8: 0.45 | K8: =IF(N8<>0, IFERROR(IF( $F8=2, MROUND($AH8*N8,1), IF( OR($F8="",$F8=1), MROUND($AH8*N8,2.5), MROUND($AH8*N8, 0.1))), "" ), "") | O8: =IF(R8<>0, IFERROR(IF( $F8=2, MROUND($AH8*R8,1), IF( OR($F8="",$F8=1), MROUND($AH8*R8,2.5), MROUND($AH8*R8, 0.1))), "" ), "") | S8: =IF(V8<>0, IFERROR(IF( $F8=2, MROUND($AH8*V8,1), IF( OR($F8="",$F8=1), MROUND($AH8*V8,2.5), MROUND($AH8*V8, 0.1))), "" ), "") | W8: =IF(Z8<>0, IFERROR(IF( $F8=2, MROUND($AH8*Z8,1), IF( OR($F8="",$F8=1), MROUND($AH8*Z8,2.5), MROUND($AH8*Z8, 0.1))), "" ), "") | AA8: =IF(AD8<>0, IFERROR(IF( $F8=2, MROUND($AH8*AD8,1), IF( OR($F8="",$F8=1), MROUND($AH8*AD8,2.5), MROUND($AH8*AD8, 0.1))), "" ), "") | AE8: =(IF(ISNUMBER(G8),G8,0)*H8*I8+IF(ISNUMBER(K8),K8,1)*L8*M8+IF(ISNUMBER(O8),O8,1)*P8*Q8+IF(ISNUMBER(S8),S8,1)*T8*U8+IF(ISNUMBER(W8),W8,1)*X8*Y8+IF(ISNUMBER(AA8),AA8,1)*AB8*AC8)*IF(ISNUMBER(F8),F8,1) -> 500 | AF8: =IFERROR(AE8/AJ8,0) -> 20 | AG8: =IFERROR((AF8/(AH8*IF(ISNUMBER(F8),F8,1))),0) -> 0.4576659 | AH8: =AH5*0.46 -> 43.7 | AI8: =( IF(ISNUMBER(G8), VLOOKUP(G8/$AH8,F!$A1:$B101,2,1)*G8*$H8*$I8,0)+IF(ISNUMBER(K8), VLOOKUP(K8/$AH8,F!$A1:$B101,2,1)*K8*$L8*$M8,0)+IF(ISNUMBER(O8), VLOOKUP(O8/$AH8,F!$A1:$B101,2,1)*O8*$P8*$Q8,0)+IF(ISNUMBER(S8), VLOOKUP(S8/$AH8,F!$A1:$B101,2,1)*S8*$T8*$U8,0)+IF(ISNUMBER(W8), VLOOKUP(W8/$AH8,F!$A1:$B101,2,1)*W8*$X8*$Y8,0)+IF(ISNUMBER(AA8), VLOOKUP(AA8/$AH8,F!$A1:$B101,2,1)*AA8*$AB8*$AC8,0))*IF(ISNUMBER(F8),F8,1)*IF(ISNUMBER(E8),E8,1) -> 84 | AJ8: =H8*I8+L8*M8+P8*Q8+T8*U8+X8*Y8+AB8*AC8 -> 25 | AK8: {=IFERROR(I8*INDEX(F!$P$21:$AB$33, MATCH(G8/$AH8, F!$O$21:$O$33,1), MATCH(E8, F!$P$20:$AB$20,1)), 0 ) +IFERROR( M8*INDEX(F!$P$21:$AB$33, MATCH(K8/$AH8, F!$O$21:$O$33,1), MATCH(E8, F!$P$20:$AB$20,1)),0) + IFERROR( Q8*INDEX(F!$P$21:$AB$33, MATCH(O8/$AH8, F!$O$21:$O$33,1), MATCH(E8, F!$P$20:$AB$20,1)), 0) + IFERROR( U8*INDEX(F!$P$21:$AB$33, MATCH(S8/$AH8, F!$O$21:$O$33,1), MATCH(E8, F!$P$20:$AB$20,1)),0) + IFERROR(Y8*INDEX(F!$P$21:$AB$33, MATCH(W8/$AH8, F!$O$21:$O$33,1), MATCH(E8, F!$P$20:$AB$20,1)),0) + IFERROR( AC8*INDEX(F!$P$21:$AB$33, MATCH(AA8/$AH8, F!$O$21:$O$33,1), MATCH(E8, F!$P$20:$AB$20,1)),)} -> 7.5
K9: =IF(N9<>0, IFERROR(IF( $F9=2, MROUND($AH9*N9,1), IF( OR($F9="",$F9=1), MROUND($AH9*N9,2.5), MROUND($AH9*N9, 0.1))), "" ), "") | O9: =IF(R9<>0, IFERROR(IF( $F9=2, MROUND($AH9*R9,1), IF( OR($F9="",$F9=1), MROUND($AH9*R9,2.5), MROUND($AH9*R9, 0.1))), "" ), "") | S9: =IF(V9<>0, IFERROR(IF( $F9=2, MROUND($AH9*V9,1), IF( OR($F9="",$F9=1), MROUND($AH9*V9,2.5), MROUND($AH9*V9, 0.1))), "" ), "") | W9: =IF(Z9<>0, IFERROR(IF( $F9=2, MROUND($AH9*Z9,1), IF( OR($F9="",$F9=1), MROUND($AH9*Z9,2.5), MROUND($AH9*Z9, 0.1))), "" ), "") | AA9: =IF(AD9<>0, IFERROR(IF( $F9=2, MROUND($AH9*AD9,1), IF( OR($F9="",$F9=1), MROUND($AH9*AD9,2.5), MROUND($AH9*AD9, 0.1))), "" ), "") | AE9: =(IF(ISNUMBER(G9),G9,0)*H9*I9+IF(ISNUMBER(K9),K9,1)*L9*M9+IF(ISNUMBER(O9),O9,1)*P9*Q9+IF(ISNUMBER(S9),S9,1)*T9*U9+IF(ISNUMBER(W9),W9,1)*X9*Y9+IF(ISNUMBER(AA9),AA9,1)*AB9*AC9)*IF(ISNUMBER(F9),F9,1) -> 0 | AF9: =IFERROR(AE9/AJ9,0) -> 0 | AG9: =IFERROR((AF9/(AH9*IF(ISNUMBER(F9),F9,1))),0) -> 0 | AI9: =( IF(ISNUMBER(G9), VLOOKUP(G9/$AH9,F!$A1:$B101,2,1)*G9*$H9*$I9,0)+IF(ISNUMBER(K9), VLOOKUP(K9/$AH9,F!$A1:$B101,2,1)*K9*$L9*$M9,0)+IF(ISNUMBER(O9), VLOOKUP(O9/$AH9,F!$A1:$B101,2,1)*O9*$P9*$Q9,0)+IF(ISNUMBER(S9), VLOOKUP(S9/$AH9,F!$A1:$B101,2,1)*S9*$T9*$U9,0)+IF(ISNUMBER(W9), VLOOKUP(W9/$AH9,F!$A1:$B101,2,1)*W9*$X9*$Y9,0)+IF(ISNUMBER(AA9), VLOOKUP(AA9/$AH9,F!$A1:$B101,2,1)*AA9*$AB9*$AC9,0))*IF(ISNUMBER(F9),F9,1)*IF(ISNUMBER(E9),E9,1) -> 0 | AJ9: =H9*I9+L9*M9+P9*Q9+T9*U9+X9*Y9+AB9*AC9 -> 0 | AK9: {=IFERROR(I9*INDEX(F!$P$21:$AB$33, MATCH(G9/$AH9, F!$O$21:$O$33,1), MATCH(E9, F!$P$20:$AB$20,1)), 0 ) +IFERROR( M9*INDEX(F!$P$21:$AB$33, MATCH(K9/$AH9, F!$O$21:$O$33,1), MATCH(E9, F!$P$20:$AB$20,1)),0) + IFERROR( Q9*INDEX(F!$P$21:$AB$33, MATCH(O9/$AH9, F!$O$21:$O$33,1), MATCH(E9, F!$P$20:$AB$20,1)), 0) + IFERROR( U9*INDEX(F!$P$21:$AB$33, MATCH(S9/$AH9, F!$O$21:$O$33,1), MATCH(E9, F!$P$20:$AB$20,1)),0) + IFERROR(Y9*INDEX(F!$P$21:$AB$33, MATCH(W9/$AH9, F!$O$21:$O$33,1), MATCH(E9, F!$P$20:$AB$20,1)),0) + IFERROR( AC9*INDEX(F!$P$21:$AB$33, MATCH(AA9/$AH9, F!$O$21:$O$33,1), MATCH(E9, F!$P$20:$AB$20,1)),)} -> 0
K10: =IF(N10<>0, IFERROR(IF( $F10=2, MROUND($AH10*N10,1), IF( OR($F10="",$F10=1), MROUND($AH10*N10,2.5), MROUND($AH10*N10, 0.1))), "" ), "") | O10: =IF(R10<>0, IFERROR(IF( $F10=2, MROUND($AH10*R10,1), IF( OR($F10="",$F10=1), MROUND($AH10*R10,2.5), MROUND($AH10*R10, 0.1))), "" ), "") | S10: =IF(V10<>0, IFERROR(IF( $F10=2, MROUND($AH10*V10,1), IF( OR($F10="",$F10=1), MROUND($AH10*V10,2.5), MROUND($AH10*V10, 0.1))), "" ), "") | W10: =IF(Z10<>0, IFERROR(IF( $F10=2, MROUND($AH10*Z10,1), IF( OR($F10="",$F10=1), MROUND($AH10*Z10,2.5), MROUND($AH10*Z10, 0.1))), "" ), "") | AA10: =IF(AD10<>0, IFERROR(IF( $F10=2, MROUND($AH10*AD10,1), IF( OR($F10="",$F10=1), MROUND($AH10*AD10,2.5), MROUND($AH10*AD10, 0.1))), "" ), "") | AE10: =(IF(ISNUMBER(G10),G10,0)*H10*I10+IF(ISNUMBER(K10),K10,1)*L10*M10+IF(ISNUMBER(O10),O10,1)*P10*Q10+IF(ISNUMBER(S10),S10,1)*T10*U10+IF(ISNUMBER(W10),W10,1)*X10*Y10+IF(ISNUMBER(AA10),AA10,1)*AB10*AC10)*IF(ISNUMBER(F10),F10,1) -> 0 | AF10: =IFERROR(AE10/AJ10,0) -> 0 | AG10: =IFERROR((AF10/(AH10*IF(ISNUMBER(F10),F10,1))),0) -> 0 | AI10: =( IF(ISNUMBER(G10), VLOOKUP(G10/$AH10,F!$A1:$B101,2,1)*G10*$H10*$I10,0)+IF(ISNUMBER(K10), VLOOKUP(K10/$AH10,F!$A1:$B101,2,1)*K10*$L10*$M10,0)+IF(ISNUMBER(O10), VLOOKUP(O10/$AH10,F!$A1:$B101,2,1)*O10*$P10*$Q10,0)+IF(ISNUMBER(S10), VLOOKUP(S10/$AH10,F!$A1:$B101,2,1)*S10*$T10*$U10,0)+IF(ISNUMBER(W10), VLOOKUP(W10/$AH10,F!$A1:$B101,2,1)*W10*$X10*$Y10,0)+IF(ISNUMBER(AA10), VLOOKUP(AA10/$AH10,F!$A1:$B101,2,1)*AA10*$AB10*$AC10,0))*IF(ISNUMBER(F10),F10,1)*IF(ISNUMBER(E10),E10,1) -> 0 | AJ10: =H10*I10+L10*M10+P10*Q10+T10*U10+X10*Y10+AB10*AC10 -> 0 | AK10: {=IFERROR(I10*INDEX(F!$P$21:$AB$33, MATCH(G10/$AH10, F!$O$21:$O$33,1), MATCH(E10, F!$P$20:$AB$20,1)), 0 ) +IFERROR( M10*INDEX(F!$P$21:$AB$33, MATCH(K10/$AH10, F!$O$21:$O$33,1), MATCH(E10, F!$P$20:$AB$20,1)),0) + IFERROR( Q10*INDEX(F!$P$21:$AB$33, MATCH(O10/$AH10, F!$O$21:$O$33,1), MATCH(E10, F!$P$20:$AB$20,1)), 0) + IFERROR( U10*INDEX(F!$P$21:$AB$33, MATCH(S10/$AH10, F!$O$21:$O$33,1), MATCH(E10, F!$P$20:$AB$20,1)),0) + IFERROR(Y10*INDEX(F!$P$21:$AB$33, MATCH(W10/$AH10, F!$O$21:$O$33,1), MATCH(E10, F!$P$20:$AB$20,1)),0) + IFERROR( AC10*INDEX(F!$P$21:$AB$33, MATCH(AA10/$AH10, F!$O$21:$O$33,1), MATCH(E10, F!$P$20:$AB$20,1)),)} -> 0
G11: =IF(J11<>0, IFERROR(IF( $F11=2, MROUND($AH11*J11,1), IF( OR($F11="",$F11=1), MROUND($AH11*J11,2.5), MROUND($AH11*J11, 0.1))), "" ), "") | K11: =IF(N11<>0, IFERROR(IF( $F11=2, MROUND($AH11*N11,1), IF( OR($F11="",$F11=1), MROUND($AH11*N11,2.5), MROUND($AH11*N11, 0.1))), "" ), "") | O11: =IF(R11<>0, IFERROR(IF( $F11=2, MROUND($AH11*R11,1), IF( OR($F11="",$F11=1), MROUND($AH11*R11,2.5), MROUND($AH11*R11, 0.1))), "" ), "") | S11: =IF(V11<>0, IFERROR(IF( $F11=2, MROUND($AH11*V11,1), IF( OR($F11="",$F11=1), MROUND($AH11*V11,2.5), MROUND($AH11*V11, 0.1))), "" ), "") | W11: =IF(Z11<>0, IFERROR(IF( $F11=2, MROUND($AH11*Z11,1), IF( OR($F11="",$F11=1), MROUND($AH11*Z11,2.5), MROUND($AH11*Z11, 0.1))), "" ), "") | AA11: =IF(AD11<>0, IFERROR(IF( $F11=2, MROUND($AH11*AD11,1), IF( OR($F11="",$F11=1), MROUND($AH11*AD11,2.5), MROUND($AH11*AD11, 0.1))), "" ), "") | AE11: =(IF(ISNUMBER(G11),G11,0)*H11*I11+IF(ISNUMBER(K11),K11,1)*L11*M11+IF(ISNUMBER(O11),O11,1)*P11*Q11+IF(ISNUMBER(S11),S11,1)*T11*U11+IF(ISNUMBER(W11),W11,1)*X11*Y11+IF(ISNUMBER(AA11),AA11,1)*AB11*AC11)*IF(ISNUMBER(F11),F11,1) -> 0 | AF11: =IFERROR(AE11/AJ11,0) -> 0 | AG11: =IFERROR((AF11/(AH11*IF(ISNUMBER(F11),F11,1))),0) -> 0 | AI11: =( IF(ISNUMBER(G11), VLOOKUP(G11/$AH11,F!$A1:$B101,2,1)*G11*$H11*$I11,0)+IF(ISNUMBER(K11), VLOOKUP(K11/$AH11,F!$A1:$B101,2,1)*K11*$L11*$M11,0)+IF(ISNUMBER(O11), VLOOKUP(O11/$AH11,F!$A1:$B101,2,1)*O11*$P11*$Q11,0)+IF(ISNUMBER(S11), VLOOKUP(S11/$AH11,F!$A1:$B101,2,1)*S11*$T11*$U11,0)+IF(ISNUMBER(W11), VLOOKUP(W11/$AH11,F!$A1:$B101,2,1)*W11*$X11*$Y11,0)+IF(ISNUMBER(AA11), VLOOKUP(AA11/$AH11,F!$A1:$B101,2,1)*AA11*$AB11*$AC11,0))*IF(ISNUMBER(F11),F11,1)*IF(ISNUMBER(E11),E11,1) -> 0 | AJ11: =H11*I11+L11*M11+P11*Q11+T11*U11+X11*Y11+AB11*AC11 -> 0 | AK11: {=IFERROR(I11*INDEX(F!$P$21:$AB$33, MATCH(G11/$AH11, F!$O$21:$O$33,1), MATCH(E11, F!$P$20:$AB$20,1)), 0 ) +IFERROR( M11*INDEX(F!$P$21:$AB$33, MATCH(K11/$AH11, F!$O$21:$O$33,1), MATCH(E11, F!$P$20:$AB$20,1)),0) + IFERROR( Q11*INDEX(F!$P$21:$AB$33, MATCH(O11/$AH11, F!$O$21:$O$33,1), MATCH(E11, F!$P$20:$AB$20,1)), 0) + IFERROR( U11*INDEX(F!$P$21:$AB$33, MATCH(S11/$AH11, F!$O$21:$O$33,1), MATCH(E11, F!$P$20:$AB$20,1)),0) + IFERROR(Y11*INDEX(F!$P$21:$AB$33, MATCH(W11/$AH11, F!$O$21:$O$33,1), MATCH(E11, F!$P$20:$AB$20,1)),0) + IFERROR( AC11*INDEX(F!$P$21:$AB$33, MATCH(AA11/$AH11, F!$O$21:$O$33,1), MATCH(E11, F!$P$20:$AB$20,1)),)} -> 0
E12: =ROUND(IFERROR(SUMPRODUCT(AJ4:AJ11,E4:E11)/AJ12,0),3) -> 0.927 | AE12: =SUM(AE4:AE11) -> 5645 | AF12: =IFERROR(AE12/AJ12,0) -> 57.602041 | AG12: =IFERROR( SUMPRODUCT(AG4:AG11,AJ4:AJ11)/AJ12,0) -> 0.61674156 | AI12: =SUM(AI4:AI11) -> 5227.31 | AJ12: =SUM(AJ4:AJ11) -> 98 | AK12: =IF(SUM(AK4:AK11)=0,TIME(,0,),TIME(,SUM(AK4:AK11)+F!$V$37,)) -> 0.0875
A13: =A14 -> 43782 | B13: Тяжелая | C13: ТГ | D13: Становая тяга | E13: 1.4 | G13: =IF(J13<>0, IFERROR(IF( $F13=2, MROUND($AH13*J13,1), IF( OR($F13="",$F13=1), MROUND($AH13*J13,2.5), MROUND($AH13*J13, 0.1))), "" ), "") -> 110 | H13: 3 | I13: 1 | J13: 0.6 | K13: =IF(N13<>0, IFERROR(IF( $F13=2, MROUND($AH13*N13,1), IF( OR($F13="",$F13=1), MROUND($AH13*N13,2.5), MROUND($AH13*N13, 0.1))), "" ), "") -> 130 | L13: 2 | M13: 2 | N13: 0.7 | O13: =IF(R13<>0, IFERROR(IF( $F13=2, MROUND($AH13*R13,1), IF( OR($F13="",$F13=1), MROUND($AH13*R13,2.5), MROUND($AH13*R13, 0.1))), "" ), "") -> 147.5 | P13: 1 | Q13: 2 | R13: 0.8 | S13: =IF(V13<>0, IFERROR(IF( $F13=2, MROUND($AH13*V13,1), IF( OR($F13="",$F13=1), MROUND($AH13*V13,2.5), MROUND($AH13*V13, 0.1))), "" ), "") -> 152.5 | T13: 1 | U13: 2 | V13: 0.83 | W13: =IF(Z13<>0, IFERROR(IF( $F13=2, MROUND($AH13*Z13,1), IF( OR($F13="",$F13=1), MROUND($AH13*Z13,2.5), MROUND($AH13*Z13, 0.1))), "" ), "") | AA13: =IF(AD13<>0, IFERROR(IF( $F13=2, MROUND($AH13*AD13,1), IF( OR($F13="",$F13=1), MROUND($AH13*AD13,2.5), MROUND($AH13*AD13, 0.1))), "" ), "") | AE13: =(IF(ISNUMBER(G13),G13,0)*H13*I13+IF(ISNUMBER(K13),K13,1)*L13*M13+IF(ISNUMBER(O13),O13,1)*P13*Q13+IF(ISNUMBER(S13),S13,1)*T13*U13+IF(ISNUMBER(W13),W13,1)*X13*Y13+IF(ISNUMBER(AA13),AA13,1)*AB13*AC13)*IF(ISNUMBER(F13),F13,1) -> 1450 | AF13: =IFERROR(AE13/AJ13,0) -> 131.81818 | AG13: =IFERROR((AF13/(AH13*IF(ISNUMBER(F13),F13,1))),0) -> 0.71253071 | AH13: 185 | AI13: =( IF(ISNUMBER(G13), VLOOKUP(G13/$AH13,F!$A1:$B101,2,1)*G13*$H13*$I13,0)+IF(ISNUMBER(K13), VLOOKUP(K13/$AH13,F!$A1:$B101,2,1)*K13*$L13*$M13,0)+IF(ISNUMBER(O13), VLOOKUP(O13/$AH13,F!$A1:$B101,2,1)*O13*$P13*$Q13,0)+IF(ISNUMBER(S13), VLOOKUP(S13/$AH13,F!$A1:$B101,2,1)*S13*$T13*$U13,0)+IF(ISNUMBER(W13), VLOOKUP(W13/$AH13,F!$A1:$B101,2,1)*W13*$X13*$Y13,0)+IF(ISNUMBER(AA13), VLOOKUP(AA13/$AH13,F!$A1:$B101,2,1)*AA13*$AB13*$AC13,0))*IF(ISNUMBER(F13),F13,1)*IF(ISNUMBER(E13),E13,1) -> 2289.56 | AJ13: =H13*I13+L13*M13+P13*Q13+T13*U13+X13*Y13+AB13*AC13 -> 11 | AK13: {=IFERROR(I13*INDEX(F!$P$21:$AB$33, MATCH(G13/$AH13, F!$O$21:$O$33,1), MATCH(E13, F!$P$20:$AB$20,1)), 0 ) +IFERROR( M13*INDEX(F!$P$21:$AB$33, MATCH(K13/$AH13, F!$O$21:$O$33,1), MATCH(E13, F!$P$20:$AB$20,1)),0) + IFERROR( Q13*INDEX(F!$P$21:$AB$33, MATCH(O13/$AH13, F!$O$21:$O$33,1), MATCH(E13, F!$P$20:$AB$20,1)), 0) + IFERROR( U13*INDEX(F!$P$21:$AB$33, MATCH(S13/$AH13, F!$O$21:$O$33,1), MATCH(E13, F!$P$20:$AB$20,1)),0) + IFERROR(Y13*INDEX(F!$P$21:$AB$33, MATCH(W13/$AH13, F!$O$21:$O$33,1), MATCH(E13, F!$P$20:$AB$20,1)),0) + IFERROR( AC13*INDEX(F!$P$21:$AB$33, MATCH(AA13/$AH13, F!$O$21:$O$33,1), MATCH(E13, F!$P$20:$AB$20,1)),)} -> 37.5
A14: 43782 | B14: Тяжелая | C14: ЖМ | D14: Жим лежа | E14: 1 | G14: =IF(J14<>0, IFERROR(IF( $F14=2, MROUND($AH14*J14,1), IF( OR($F14="",$F14=1), MROUND($AH14*J14,2.5), MROUND($AH14*J14, 0.1))), "" ), "") -> 57.5 | H14: 3 | I14: 1 | J14: 0.6 | K14: =IF(N14<>0, IFERROR(IF( $F14=2, MROUND($AH14*N14,1), IF( OR($F14="",$F14=1), MROUND($AH14*N14,2.5), MROUND($AH14*N14, 0.1))), "" ), "") -> 67.5 | L14: 3 | M14: 5 | N14: 0.7 | O14: =IF(R14<>0, IFERROR(IF( $F14=2, MROUND($AH14*R14,1), IF( OR($F14="",$F14=1), MROUND($AH14*R14,2.5), MROUND($AH14*R14, 0.1))), "" ), "") | S14: =IF(V14<>0, IFERROR(IF( $F14=2, MROUND($AH14*V14,1), IF( OR($F14="",$F14=1), MROUND($AH14*V14,2.5), MROUND($AH14*V14, 0.1))), "" ), "") | W14: =IF(Z14<>0, IFERROR(IF( $F14=2, MROUND($AH14*Z14,1), IF( OR($F14="",$F14=1), MROUND($AH14*Z14,2.5), MROUND($AH14*Z14, 0.1))), "" ), "") | AA14: =IF(AD14<>0, IFERROR(IF( $F14=2, MROUND($AH14*AD14,1), IF( OR($F14="",$F14=1), MROUND($AH14*AD14,2.5), MROUND($AH14*AD14, 0.1))), "" ), "") | AE14: =(IF(ISNUMBER(G14),G14,0)*H14*I14+IF(ISNUMBER(K14),K14,1)*L14*M14+IF(ISNUMBER(O14),O14,1)*P14*Q14+IF(ISNUMBER(S14),S14,1)*T14*U14+IF(ISNUMBER(W14),W14,1)*X14*Y14+IF(ISNUMBER(AA14),AA14,1)*AB14*AC14)*IF(ISNUMBER(F14),F14,1) -> 1185 | AF14: =IFERROR(AE14/AJ14,0) -> 65.833333 | AG14: =IFERROR((AF14/(AH14*IF(ISNUMBER(F14),F14,1))),0) -> 0.69298246 | AH14: =AH5 -> 95 | AI14: =( IF(ISNUMBER(G14), VLOOKUP(G14/$AH14,F!$A1:$B101,2,1)*G14*$H14*$I14,0)+IF(ISNUMBER(K14), VLOOKUP(K14/$AH14,F!$A1:$B101,2,1)*K14*$L14*$M14,0)+IF(ISNUMBER(O14), VLOOKUP(O14/$AH14,F!$A1:$B101,2,1)*O14*$P14*$Q14,0)+IF(ISNUMBER(S14), VLOOKUP(S14/$AH14,F!$A1:$B101,2,1)*S14*$T14*$U14,0)+IF(ISNUMBER(W14), VLOOKUP(W14/$AH14,F!$A1:$B101,2,1)*W14*$X14*$Y14,0)+IF(ISNUMBER(AA14), VLOOKUP(AA14/$AH14,F!$A1:$B101,2,1)*AA14*$AB14*$AC14,0))*IF(ISNUMBER(F14),F14,1)*IF(ISNUMBER(E14),E14,1) -> 1082.625 | AJ14: =H14*I14+L14*M14+P14*Q14+T14*U14+X14*Y14+AB14*AC14 -> 18 | AK14: {=IFERROR(I14*INDEX(F!$P$21:$AB$33, MATCH(G14/$AH14, F!$O$21:$O$33,1), MATCH(E14, F!$P$20:$AB$20,1)), 0 ) +IFERROR( M14*INDEX(F!$P$21:$AB$33, MATCH(K14/$AH14, F!$O$21:$O$33,1), MATCH(E14, F!$P$20:$AB$20,1)),0) + IFERROR( Q14*INDEX(F!$P$21:$AB$33, MATCH(O14/$AH14, F!$O$21:$O$33,1), MATCH(E14, F!$P$20:$AB$20,1)), 0) + IFERROR( U14*INDEX(F!$P$21:$AB$33, MATCH(S14/$AH14, F!$O$21:$O$33,1), MATCH(E14, F!$P$20:$AB$20,1)),0) + IFERROR(Y14*INDEX(F!$P$21:$AB$33, MATCH(W14/$AH14, F!$O$21:$O$33,1), MATCH(E14, F!$P$20:$AB$20,1)),0) + IFERROR( AC14*INDEX(F!$P$21:$AB$33, MATCH(AA14/$AH14, F!$O$21:$O$33,1), MATCH(E14, F!$P$20:$AB$20,1)),)} -> 23
B15: Средняя | C15: ОФП | D15: Наклоны со штангой | E15: 0.8 | G15: =IF(J15<>0, IFERROR(IF( $F15=2, MROUND($AH15*J15,1), IF( OR($F15="",$F15=1), MROUND($AH15*J15,2.5), MROUND($AH15*J15, 0.1))), "" ), "") -> 55 | H15: 5 | I15: 5 | J15: 0.55 | K15: =IF(N15<>0, IFERROR(IF( $F15=2, MROUND($AH15*N15,1), IF( OR($F15="",$F15=1), MROUND($AH15*N15,2.5), MROUND($AH15*N15, 0.1))), "" ), "") | O15: =IF(R15<>0, IFERROR(IF( $F15=2, MROUND($AH15*R15,1), IF( OR($F15="",$F15=1), MROUND($AH15*R15,2.5), MROUND($AH15*R15, 0.1))), "" ), "") | S15: =IF(V15<>0, IFERROR(IF( $F15=2, MROUND($AH15*V15,1), IF( OR($F15="",$F15=1), MROUND($AH15*V15,2.5), MROUND($AH15*V15, 0.1))), "" ), "") | W15: =IF(Z15<>0, IFERROR(IF( $F15=2, MROUND($AH15*Z15,1), IF( OR($F15="",$F15=1), MROUND($AH15*Z15,2.5), MROUND($AH15*Z15, 0.1))), "" ), "") | AA15: =IF(AD15<>0, IFERROR(IF( $F15=2, MROUND($AH15*AD15,1), IF( OR($F15="",$F15=1), MROUND($AH15*AD15,2.5), MROUND($AH15*AD15, 0.1))), "" ), "") | AE15: =(IF(ISNUMBER(G15),G15,0)*H15*I15+IF(ISNUMBER(K15),K15,1)*L15*M15+IF(ISNUMBER(O15),O15,1)*P15*Q15+IF(ISNUMBER(S15),S15,1)*T15*U15+IF(ISNUMBER(W15),W15,1)*X15*Y15+IF(ISNUMBER(AA15),AA15,1)*AB15*AC15)*IF(ISNUMBER(F15),F15,1) -> 1375 | AF15: =IFERROR(AE15/AJ15,0) -> 55 | AG15: =IFERROR((AF15/(AH15*IF(ISNUMBER(F15),F15,1))),0) -> 0.54054054 | AH15: =AH13*0.55 -> 101.75 | AI15: =( IF(ISNUMBER(G15), VLOOKUP(G15/$AH15,F!$A1:$B101,2,1)*G15*$H15*$I15,0)+IF(ISNUMBER(K15), VLOOKUP(K15/$AH15,F!$A1:$B101,2,1)*K15*$L15*$M15,0)+IF(ISNUMBER(O15), VLOOKUP(O15/$AH15,F!$A1:$B101,2,1)*O15*$P15*$Q15,0)+IF(ISNUMBER(S15), VLOOKUP(S15/$AH15,F!$A1:$B101,2,1)*S15*$T15*$U15,0)+IF(ISNUMBER(W15), VLOOKUP(W15/$AH15,F!$A1:$B101,2,1)*W15*$X15*$Y15,0)+IF(ISNUMBER(AA15), VLOOKUP(AA15/$AH15,F!$A1:$B101,2,1)*AA15*$AB15*$AC15,0))*IF(ISNUMBER(F15),F15,1)*IF(ISNUMBER(E15),E15,1) -> 616 | AJ15: =H15*I15+L15*M15+P15*Q15+T15*U15+X15*Y15+AB15*AC15 -> 25 | AK15: {=IFERROR(I15*INDEX(F!$P$21:$AB$33, MATCH(G15/$AH15, F!$O$21:$O$33,1), MATCH(E15, F!$P$20:$AB$20,1)), 0 ) +IFERROR( M15*INDEX(F!$P$21:$AB$33, MATCH(K15/$AH15, F!$O$21:$O$33,1), MATCH(E15, F!$P$20:$AB$20,1)),0) + IFERROR( Q15*INDEX(F!$P$21:$AB$33, MATCH(O15/$AH15, F!$O$21:$O$33,1), MATCH(E15, F!$P$20:$AB$20,1)), 0) + IFERROR( U15*INDEX(F!$P$21:$AB$33, MATCH(S15/$AH15, F!$O$21:$O$33,1), MATCH(E15, F!$P$20:$AB$20,1)),0) + IFERROR(Y15*INDEX(F!$P$21:$AB$33, MATCH(W15/$AH15, F!$O$21:$O$33,1), MATCH(E15, F!$P$20:$AB$20,1)),0) + IFERROR( AC15*INDEX(F!$P$21:$AB$33, MATCH(AA15/$AH15, F!$O$21:$O$33,1), MATCH(E15, F!$P$20:$AB$20,1)),)} -> 9
B16: Легкая | C16: ОФП | D16: Жим стоя | E16: 1 | G16: =IF(J16<>0, IFERROR(IF( $F16=2, MROUND($AH16*J16,1), IF( OR($F16="",$F16=1), MROUND($AH16*J16,2.5), MROUND($AH16*J16, 0.1))), "" ), "") -> 22.5 | H16: 6 | I16: 4 | J16: 0.4 | K16: =IF(N16<>0, IFERROR(IF( $F16=2, MROUND($AH16*N16,1), IF( OR($F16="",$F16=1), MROUND($AH16*N16,2.5), MROUND($AH16*N16, 0.1))), "" ), "") -> 25 | L16: 5 | M16: 4 | N16: 0.45 | O16: =IF(R16<>0, IFERROR(IF( $F16=2, MROUND($AH16*R16,1), IF( OR($F16="",$F16=1), MROUND($AH16*R16,2.5), MROUND($AH16*R16, 0.1))), "" ), "") | S16: =IF(V16<>0, IFERROR(IF( $F16=2, MROUND($AH16*V16,1), IF( OR($F16="",$F16=1), MROUND($AH16*V16,2.5), MROUND($AH16*V16, 0.1))), "" ), "") | W16: =IF(Z16<>0, IFERROR(IF( $F16=2, MROUND($AH16*Z16,1), IF( OR($F16="",$F16=1), MROUND($AH16*Z16,2.5), MROUND($AH16*Z16, 0.1))), "" ), "") | AA16: =IF(AD16<>0, IFERROR(IF( $F16=2, MROUND($AH16*AD16,1), IF( OR($F16="",$F16=1), MROUND($AH16*AD16,2.5), MROUND($AH16*AD16, 0.1))), "" ), "") | AE16: =(IF(ISNUMBER(G16),G16,0)*H16*I16+IF(ISNUMBER(K16),K16,1)*L16*M16+IF(ISNUMBER(O16),O16,1)*P16*Q16+IF(ISNUMBER(S16),S16,1)*T16*U16+IF(ISNUMBER(W16),W16,1)*X16*Y16+IF(ISNUMBER(AA16),AA16,1)*AB16*AC16)*IF(ISNUMBER(F16),F16,1) -> 1040 | AF16: =IFERROR(AE16/AJ16,0) -> 23.636364 | AG16: =IFERROR((AF16/(AH16*IF(ISNUMBER(F16),F16,1))),0) -> 0.41467305 | AH16: =AH14*0.6 -> 57 | AI16: =( IF(ISNUMBER(G16), VLOOKUP(G16/$AH16,F!$A1:$B101,2,1)*G16*$H16*$I16,0)+IF(ISNUMBER(K16), VLOOKUP(K16/$AH16,F!$A1:$B101,2,1)*K16*$L16*$M16,0)+IF(ISNUMBER(O16), VLOOKUP(O16/$AH16,F!$A1:$B101,2,1)*O16*$P16*$Q16,0)+IF(ISNUMBER(S16), VLOOKUP(S16/$AH16,F!$A1:$B101,2,1)*S16*$T16*$U16,0)+IF(ISNUMBER(W16), VLOOKUP(W16/$AH16,F!$A1:$B101,2,1)*W16*$X16*$Y16,0)+IF(ISNUMBER(AA16), VLOOKUP(AA16/$AH16,F!$A1:$B101,2,1)*AA16*$AB16*$AC16,0))*IF(ISNUMBER(F16),F16,1)*IF(ISNUMBER(E16),E16,1) -> 352 | AJ16: =H16*I16+L16*M16+P16*Q16+T16*U16+X16*Y16+AB16*AC16 -> 44 | AK16: {=IFERROR(I16*INDEX(F!$P$21:$AB$33, MATCH(G16/$AH16, F!$O$21:$O$33,1), MATCH(E16, F!$P$20:$AB$20,1)), 0 ) +IFERROR( M16*INDEX(F!$P$21:$AB$33, MATCH(K16/$AH16, F!$O$21:$O$33,1), MATCH(E16, F!$P$20:$AB$20,1)),0) + IFERROR( Q16*INDEX(F!$P$21:$AB$33, MATCH(O16/$AH16, F!$O$21:$O$33,1), MATCH(E16, F!$P$20:$AB$20,1)), 0) + IFERROR( U16*INDEX(F!$P$21:$AB$33, MATCH(S16/$AH16, F!$O$21:$O$33,1), MATCH(E16, F!$P$20:$AB$20,1)),0) + IFERROR(Y16*INDEX(F!$P$21:$AB$33, MATCH(W16/$AH16, F!$O$21:$O$33,1), MATCH(E16, F!$P$20:$AB$20,1)),0) + IFERROR( AC16*INDEX(F!$P$21:$AB$33, MATCH(AA16/$AH16, F!$O$21:$O$33,1), MATCH(E16, F!$P$20:$AB$20,1)),)} -> 16
B17: Тяжелая | C17: ЖМ | D17: Жим средним хватом | E17: 1 | G17: =IF(J17<>0, IFERROR(IF( $F17=2, MROUND($AH17*J17,1), IF( OR($F17="",$F17=1), MROUND($AH17*J17,2.5), MROUND($AH17*J17, 0.1))), "" ), "") -> 45 | H17: 4 | I17: 1 | J17: 0.55 | K17: =IF(N17<>0, IFERROR(IF( $F17=2, MROUND($AH17*N17,1), IF( OR($F17="",$F17=1), MROUND($AH17*N17,2.5), MROUND($AH17*N17, 0.1))), "" ), "") -> 52.5 | L17: 3 | M17: 1 | N17: 0.65 | O17: =IF(R17<>0, IFERROR(IF( $F17=2, MROUND($AH17*R17,1), IF( OR($F17="",$F17=1), MROUND($AH17*R17,2.5), MROUND($AH17*R17, 0.1))), "" ), "") -> 60 | P17: 2 | Q17: 2 | R17: 0.75 | S17: =IF(V17<>0, IFERROR(IF( $F17=2, MROUND($AH17*V17,1), IF( OR($F17="",$F17=1), MROUND($AH17*V17,2.5), MROUND($AH17*V17, 0.1))), "" ), "") -> 67.5 | T17: 2 | U17: 2 | V17: 0.85 | W17: =IF(Z17<>0, IFERROR(IF( $F17=2, MROUND($AH17*Z17,1), IF( OR($F17="",$F17=1), MROUND($AH17*Z17,2.5), MROUND($AH17*Z17, 0.1))), "" ), "") | AA17: =IF(AD17<>0, IFERROR(IF( $F17=2, MROUND($AH17*AD17,1), IF( OR($F17="",$F17=1), MROUND($AH17*AD17,2.5), MROUND($AH17*AD17, 0.1))), "" ), "") | AE17: =(IF(ISNUMBER(G17),G17,0)*H17*I17+IF(ISNUMBER(K17),K17,1)*L17*M17+IF(ISNUMBER(O17),O17,1)*P17*Q17+IF(ISNUMBER(S17),S17,1)*T17*U17+IF(ISNUMBER(W17),W17,1)*X17*Y17+IF(ISNUMBER(AA17),AA17,1)*AB17*AC17)*IF(ISNUMBER(F17),F17,1) -> 847.5 | AF17: =IFERROR(AE17/AJ17,0) -> 56.5 | AG17: =IFERROR((AF17/(AH17*IF(ISNUMBER(F17),F17,1))),0) -> 0.6996904 | AH17: =AH14*0.85 -> 80.75 | AI17: =( IF(ISNUMBER(G17), VLOOKUP(G17/$AH17,F!$A1:$B101,2,1)*G17*$H17*$I17,0)+IF(ISNUMBER(K17), VLOOKUP(K17/$AH17,F!$A1:$B101,2,1)*K17*$L17*$M17,0)+IF(ISNUMBER(O17), VLOOKUP(O17/$AH17,F!$A1:$B101,2,1)*O17*$P17*$Q17,0)+IF(ISNUMBER(S17), VLOOKUP(S17/$AH17,F!$A1:$B101,2,1)*S17*$T17*$U17,0)+IF(ISNUMBER(W17), VLOOKUP(W17/$AH17,F!$A1:$B101,2,1)*W17*$X17*$Y17,0)+IF(ISNUMBER(AA17), VLOOKUP(AA17/$AH17,F!$A1:$B101,2,1)*AA17*$AB17*$AC17,0))*IF(ISNUMBER(F17),F17,1)*IF(ISNUMBER(E17),E17,1) -> 973.8 | AJ17: =H17*I17+L17*M17+P17*Q17+T17*U17+X17*Y17+AB17*AC17 -> 15 | AK17: {=IFERROR(I17*INDEX(F!$P$21:$AB$33, MATCH(G17/$AH17, F!$O$21:$O$33,1), MATCH(E17, F!$P$20:$AB$20,1)), 0 ) +IFERROR( M17*INDEX(F!$P$21:$AB$33, MATCH(K17/$AH17, F!$O$21:$O$33,1), MATCH(E17, F!$P$20:$AB$20,1)),0) + IFERROR( Q17*INDEX(F!$P$21:$AB$33, MATCH(O17/$AH17, F!$O$21:$O$33,1), MATCH(E17, F!$P$20:$AB$20,1)), 0) + IFERROR( U17*INDEX(F!$P$21:$AB$33, MATCH(S17/$AH17, F!$O$21:$O$33,1), MATCH(E17, F!$P$20:$AB$20,1)),0) + IFERROR(Y17*INDEX(F!$P$21:$AB$33, MATCH(W17/$AH17, F!$O$21:$O$33,1), MATCH(E17, F!$P$20:$AB$20,1)),0) + IFERROR( AC17*INDEX(F!$P$21:$AB$33, MATCH(AA17/$AH17, F!$O$21:$O$33,1), MATCH(E17, F!$P$20:$AB$20,1)),)} -> 22
K18: =IF(N18<>0, IFERROR(IF( $F18=2, MROUND($AH18*N18,1), IF( OR($F18="",$F18=1), MROUND($AH18*N18,2.5), MROUND($AH18*N18, 0.1))), "" ), "") | O18: =IF(R18<>0, IFERROR(IF( $F18=2, MROUND($AH18*R18,1), IF( OR($F18="",$F18=1), MROUND($AH18*R18,2.5), MROUND($AH18*R18, 0.1))), "" ), "") | S18: =IF(V18<>0, IFERROR(IF( $F18=2, MROUND($AH18*V18,1), IF( OR($F18="",$F18=1), MROUND($AH18*V18,2.5), MROUND($AH18*V18, 0.1))), "" ), "") | W18: =IF(Z18<>0, IFERROR(IF( $F18=2, MROUND($AH18*Z18,1), IF( OR($F18="",$F18=1), MROUND($AH18*Z18,2.5), MROUND($AH18*Z18, 0.1))), "" ), "") | AA18: =IF(AD18<>0, IFERROR(IF( $F18=2, MROUND($AH18*AD18,1), IF( OR($F18="",$F18=1), MROUND($AH18*AD18,2.5), MROUND($AH18*AD18, 0.1))), "" ), "") | AE18: =(IF(ISNUMBER(G18),G18,0)*H18*I18+IF(ISNUMBER(K18),K18,1)*L18*M18+IF(ISNUMBER(O18),O18,1)*P18*Q18+IF(ISNUMBER(S18),S18,1)*T18*U18+IF(ISNUMBER(W18),W18,1)*X18*Y18+IF(ISNUMBER(AA18),AA18,1)*AB18*AC18)*IF(ISNUMBER(F18),F18,1) -> 0 | AF18: =IFERROR(AE18/AJ18,0) -> 0 | AG18: =IFERROR((AF18/(AH18*IF(ISNUMBER(F18),F18,1))),0) -> 0 | AI18: =( IF(ISNUMBER(G18), VLOOKUP(G18/$AH18,F!$A1:$B101,2,1)*G18*$H18*$I18,0)+IF(ISNUMBER(K18), VLOOKUP(K18/$AH18,F!$A1:$B101,2,1)*K18*$L18*$M18,0)+IF(ISNUMBER(O18), VLOOKUP(O18/$AH18,F!$A1:$B101,2,1)*O18*$P18*$Q18,0)+IF(ISNUMBER(S18), VLOOKUP(S18/$AH18,F!$A1:$B101,2,1)*S18*$T18*$U18,0)+IF(ISNUMBER(W18), VLOOKUP(W18/$AH18,F!$A1:$B101,2,1)*W18*$X18*$Y18,0)+IF(ISNUMBER(AA18), VLOOKUP(AA18/$AH18,F!$A1:$B101,2,1)*AA18*$AB18*$AC18,0))*IF(ISNUMBER(F18),F18,1)*IF(ISNUMBER(E18),E18,1) -> 0 | AJ18: =H18*I18+L18*M18+P18*Q18+T18*U18+X18*Y18+AB18*AC18 -> 0 | AK18: {=IFERROR(I18*INDEX(F!$P$21:$AB$33, MATCH(G18/$AH18, F!$O$21:$O$33,1), MATCH(E18, F!$P$20:$AB$20,1)), 0 ) +IFERROR( M18*INDEX(F!$P$21:$AB$33, MATCH(K18/$AH18, F!$O$21:$O$33,1), MATCH(E18, F!$P$20:$AB$20,1)),0) + IFERROR( Q18*INDEX(F!$P$21:$AB$33, MATCH(O18/$AH18, F!$O$21:$O$33,1), MATCH(E18, F!$P$20:$AB$20,1)), 0) + IFERROR( U18*INDEX(F!$P$21:$AB$33, MATCH(S18/$AH18, F!$O$21:$O$33,1), MATCH(E18, F!$P$20:$AB$20,1)),0) + IFERROR(Y18*INDEX(F!$P$21:$AB$33, MATCH(W18/$AH18, F!$O$21:$O$33,1), MATCH(E18, F!$P$20:$AB$20,1)),0) + IFERROR( AC18*INDEX(F!$P$21:$AB$33, MATCH(AA18/$AH18, F!$O$21:$O$33,1), MATCH(E18, F!$P$20:$AB$20,1)),)} -> 0
K19: =IF(N19<>0, IFERROR(IF( $F19=2, MROUND($AH19*N19,1), IF( OR($F19="",$F19=1), MROUND($AH19*N19,2.5), MROUND($AH19*N19, 0.1))), "" ), "") | O19: =IF(R19<>0, IFERROR(IF( $F19=2, MROUND($AH19*R19,1), IF( OR($F19="",$F19=1), MROUND($AH19*R19,2.5), MROUND($AH19*R19, 0.1))), "" ), "") | S19: =IF(V19<>0, IFERROR(IF( $F19=2, MROUND($AH19*V19,1), IF( OR($F19="",$F19=1), MROUND($AH19*V19,2.5), MROUND($AH19*V19, 0.1))), "" ), "") | W19: =IF(Z19<>0, IFERROR(IF( $F19=2, MROUND($AH19*Z19,1), IF( OR($F19="",$F19=1), MROUND($AH19*Z19,2.5), MROUND($AH19*Z19, 0.1))), "" ), "") | AA19: =IF(AD19<>0, IFERROR(IF( $F19=2, MROUND($AH19*AD19,1), IF( OR($F19="",$F19=1), MROUND($AH19*AD19,2.5), MROUND($AH19*AD19, 0.1))), "" ), "") | AE19: =(IF(ISNUMBER(G19),G19,0)*H19*I19+IF(ISNUMBER(K19),K19,1)*L19*M19+IF(ISNUMBER(O19),O19,1)*P19*Q19+IF(ISNUMBER(S19),S19,1)*T19*U19+IF(ISNUMBER(W19),W19,1)*X19*Y19+IF(ISNUMBER(AA19),AA19,1)*AB19*AC19)*IF(ISNUMBER(F19),F19,1) -> 0 | AF19: =IFERROR(AE19/AJ19,0) -> 0 | AG19: =IFERROR((AF19/(AH19*IF(ISNUMBER(F19),F19,1))),0) -> 0 | AI19: =( IF(ISNUMBER(G19), VLOOKUP(G19/$AH19,F!$A1:$B101,2,1)*G19*$H19*$I19,0)+IF(ISNUMBER(K19), VLOOKUP(K19/$AH19,F!$A1:$B101,2,1)*K19*$L19*$M19,0)+IF(ISNUMBER(O19), VLOOKUP(O19/$AH19,F!$A1:$B101,2,1)*O19*$P19*$Q19,0)+IF(ISNUMBER(S19), VLOOKUP(S19/$AH19,F!$A1:$B101,2,1)*S19*$T19*$U19,0)+IF(ISNUMBER(W19), VLOOKUP(W19/$AH19,F!$A1:$B101,2,1)*W19*$X19*$Y19,0)+IF(ISNUMBER(AA19), VLOOKUP(AA19/$AH19,F!$A1:$B101,2,1)*AA19*$AB19*$AC19,0))*IF(ISNUMBER(F19),F19,1)*IF(ISNUMBER(E19),E19,1) -> 0 | AJ19: =H19*I19+L19*M19+P19*Q19+T19*U19+X19*Y19+AB19*AC19 -> 0 | AK19: {=IFERROR(I19*INDEX(F!$P$21:$AB$33, MATCH(G19/$AH19, F!$O$21:$O$33,1), MATCH(E19, F!$P$20:$AB$20,1)), 0 ) +IFERROR( M19*INDEX(F!$P$21:$AB$33, MATCH(K19/$AH19, F!$O$21:$O$33,1), MATCH(E19, F!$P$20:$AB$20,1)),0) + IFERROR( Q19*INDEX(F!$P$21:$AB$33, MATCH(O19/$AH19, F!$O$21:$O$33,1), MATCH(E19, F!$P$20:$AB$20,1)), 0) + IFERROR( U19*INDEX(F!$P$21:$AB$33, MATCH(S19/$AH19, F!$O$21:$O$33,1), MATCH(E19, F!$P$20:$AB$20,1)),0) + IFERROR(Y19*INDEX(F!$P$21:$AB$33, MATCH(W19/$AH19, F!$O$21:$O$33,1), MATCH(E19, F!$P$20:$AB$20,1)),0) + IFERROR( AC19*INDEX(F!$P$21:$AB$33, MATCH(AA19/$AH19, F!$O$21:$O$33,1), MATCH(E19, F!$P$20:$AB$20,1)),)} -> 0
G20: =IF(J20<>0, IFERROR(IF( $F20=2, MROUND($AH20*J20,1), IF( OR($F20="",$F20=1), MROUND($AH20*J20,2.5), MROUND($AH20*J20, 0.1))), "" ), "") | K20: =IF(N20<>0, IFERROR(IF( $F20=2, MROUND($AH20*N20,1), IF( OR($F20="",$F20=1), MROUND($AH20*N20,2.5), MROUND($AH20*N20, 0.1))), "" ), "") | O20: =IF(R20<>0, IFERROR(IF( $F20=2, MROUND($AH20*R20,1), IF( OR($F20="",$F20=1), MROUND($AH20*R20,2.5), MROUND($AH20*R20, 0.1))), "" ), "") | S20: =IF(V20<>0, IFERROR(IF( $F20=2, MROUND($AH20*V20,1), IF( OR($F20="",$F20=1), MROUND($AH20*V20,2.5), MROUND($AH20*V20, 0.1))), "" ), "") | W20: =IF(Z20<>0, IFERROR(IF( $F20=2, MROUND($AH20*Z20,1), IF( OR($F20="",$F20=1), MROUND($AH20*Z20,2.5), MROUND($AH20*Z20, 0.1))), "" ), "") | AA20: =IF(AD20<>0, IFERROR(IF( $F20=2, MROUND($AH20*AD20,1), IF( OR($F20="",$F20=1), MROUND($AH20*AD20,2.5), MROUND($AH20*AD20, 0.1))), "" ), "") | AE20: =(IF(ISNUMBER(G20),G20,0)*H20*I20+IF(ISNUMBER(K20),K20,1)*L20*M20+IF(ISNUMBER(O20),O20,1)*P20*Q20+IF(ISNUMBER(S20),S20,1)*T20*U20+IF(ISNUMBER(W20),W20,1)*X20*Y20+IF(ISNUMBER(AA20),AA20,1)*AB20*AC20)*IF(ISNUMBER(F20),F20,1) -> 0 | AF20: =IFERROR(AE20/AJ20,0) -> 0 | AG20: =IFERROR((AF20/(AH20*IF(ISNUMBER(F20),F20,1))),0) -> 0 | AI20: =( IF(ISNUMBER(G20), VLOOKUP(G20/$AH20,F!$A1:$B101,2,1)*G20*$H20*$I20,0)+IF(ISNUMBER(K20), VLOOKUP(K20/$AH20,F!$A1:$B101,2,1)*K20*$L20*$M20,0)+IF(ISNUMBER(O20), VLOOKUP(O20/$AH20,F!$A1:$B101,2,1)*O20*$P20*$Q20,0)+IF(ISNUMBER(S20), VLOOKUP(S20/$AH20,F!$A1:$B101,2,1)*S20*$T20*$U20,0)+IF(ISNUMBER(W20), VLOOKUP(W20/$AH20,F!$A1:$B101,2,1)*W20*$X20*$Y20,0)+IF(ISNUMBER(AA20), VLOOKUP(AA20/$AH20,F!$A1:$B101,2,1)*AA20*$AB20*$AC20,0))*IF(ISNUMBER(F20),F20,1)*IF(ISNUMBER(E20),E20,1) -> 0 | AJ20: =H20*I20+L20*M20+P20*Q20+T20*U20+X20*Y20+AB20*AC20 -> 0 | AK20: {=IFERROR(I20*INDEX(F!$P$21:$AB$33, MATCH(G20/$AH20, F!$O$21:$O$33,1), MATCH(E20, F!$P$20:$AB$20,1)), 0 ) +IFERROR( M20*INDEX(F!$P$21:$AB$33, MATCH(K20/$AH20, F!$O$21:$O$33,1), MATCH(E20, F!$P$20:$AB$20,1)),0) + IFERROR( Q20*INDEX(F!$P$21:$AB$33, MATCH(O20/$AH20, F!$O$21:$O$33,1), MATCH(E20, F!$P$20:$AB$20,1)), 0) + IFERROR( U20*INDEX(F!$P$21:$AB$33, MATCH(S20/$AH20, F!$O$21:$O$33,1), MATCH(E20, F!$P$20:$AB$20,1)),0) + IFERROR(Y20*INDEX(F!$P$21:$AB$33, MATCH(W20/$AH20, F!$O$21:$O$33,1), MATCH(E20, F!$P$20:$AB$20,1)),0) + IFERROR( AC20*INDEX(F!$P$21:$AB$33, MATCH(AA20/$AH20, F!$O$21:$O$33,1), MATCH(E20, F!$P$20:$AB$20,1)),)} -> 0
E21: =ROUND(IFERROR(SUMPRODUCT(AJ13:AJ20,E13:E20)/AJ21,0),3) -> 0.995 | AE21: =SUM(AE13:AE20) -> 5897.5 | AF21: =IFERROR(AE21/AJ21,0) -> 52.190265 | AG21: =IFERROR( SUMPRODUCT(AG13:AG20,AJ13:AJ20)/AJ21,0) -> 0.55368147 | AI21: =SUM(AI13:AI20) -> 5313.985 | AJ21: =SUM(AJ13:AJ20) -> 113 | AK21: =IF(SUM(AK13:AK20)=0,TIME(,0,),TIME(,SUM(AK13:AK20)+F!$V$37,)) -> 0.095138889
A22: =A23 -> 43784 | B22: Тяжелая | C22: ПР | D22: Присед | E22: 1.2 | G22: =IF(J22<>0, IFERROR(IF( $F22=2, MROUND($AH22*J22,1), IF( OR($F22="",$F22=1), MROUND($AH22*J22,2.5), MROUND($AH22*J22, 0.1))), "" ), "") -> 87.5 | H22: 3 | I22: 1 | J22: 0.65 | K22: =IF(N22<>0, IFERROR(IF( $F22=2, MROUND($AH22*N22,1), IF( OR($F22="",$F22=1), MROUND($AH22*N22,2.5), MROUND($AH22*N22, 0.1))), "" ), "") -> 102.5 | L22: 2 | M22: 2 | N22: 0.75 | O22: =IF(R22<>0, IFERROR(IF( $F22=2, MROUND($AH22*R22,1), IF( OR($F22="",$F22=1), MROUND($AH22*R22,2.5), MROUND($AH22*R22, 0.1))), "" ), "") -> 115 | P22: 1 | Q22: 2 | R22: 0.85 | S22: =IF(V22<>0, IFERROR(IF( $F22=2, MROUND($AH22*V22,1), IF( OR($F22="",$F22=1), MROUND($AH22*V22,2.5), MROUND($AH22*V22, 0.1))), "" ), "") | W22: =IF(Z22<>0, IFERROR(IF( $F22=2, MROUND($AH22*Z22,1), IF( OR($F22="",$F22=1), MROUND($AH22*Z22,2.5), MROUND($AH22*Z22, 0.1))), "" ), "") | AA22: =IF(AD22<>0, IFERROR(IF( $F22=2, MROUND($AH22*AD22,1), IF( OR($F22="",$F22=1), MROUND($AH22*AD22,2.5), MROUND($AH22*AD22, 0.1))), "" ), "") | AE22: =(IF(ISNUMBER(G22),G22,0)*H22*I22+IF(ISNUMBER(K22),K22,1)*L22*M22+IF(ISNUMBER(O22),O22,1)*P22*Q22+IF(ISNUMBER(S22),S22,1)*T22*U22+IF(ISNUMBER(W22),W22,1)*X22*Y22+IF(ISNUMBER(AA22),AA22,1)*AB22*AC22)*IF(ISNUMBER(F22),F22,1) -> 902.5 | AF22: =IFERROR(AE22/AJ22,0) -> 100.27778 | AG22: =IFERROR((AF22/(AH22*IF(ISNUMBER(F22),F22,1))),0) -> 0.74279835 | AH22: =AH4 -> 135 | AI22: =( IF(ISNUMBER(G22), VLOOKUP(G22/$AH22,F!$A1:$B101,2,1)*G22*$H22*$I22,0)+IF(ISNUMBER(K22), VLOOKUP(K22/$AH22,F!$A1:$B101,2,1)*K22*$L22*$M22,0)+IF(ISNUMBER(O22), VLOOKUP(O22/$AH22,F!$A1:$B101,2,1)*O22*$P22*$Q22,0)+IF(ISNUMBER(S22), VLOOKUP(S22/$AH22,F!$A1:$B101,2,1)*S22*$T22*$U22,0)+IF(ISNUMBER(W22), VLOOKUP(W22/$AH22,F!$A1:$B101,2,1)*W22*$X22*$Y22,0)+IF(ISNUMBER(AA22), VLOOKUP(AA22/$AH22,F!$A1:$B101,2,1)*AA22*$AB22*$AC22,0))*IF(ISNUMBER(F22),F22,1)*IF(ISNUMBER(E22),E22,1) -> 1360.5 | AJ22: =H22*I22+L22*M22+P22*Q22+T22*U22+X22*Y22+AB22*AC22 -> 9 | AK22: {=IFERROR(I22*INDEX(F!$P$21:$AB$33, MATCH(G22/$AH22, F!$O$21:$O$33,1), MATCH(E22, F!$P$20:$AB$20,1)), 0 ) +IFERROR( M22*INDEX(F!$P$21:$AB$33, MATCH(K22/$AH22, F!$O$21:$O$33,1), MATCH(E22, F!$P$20:$AB$20,1)),0) + IFERROR( Q22*INDEX(F!$P$21:$AB$33, MATCH(O22/$AH22, F!$O$21:$O$33,1), MATCH(E22, F!$P$20:$AB$20,1)), 0) + IFERROR( U22*INDEX(F!$P$21:$AB$33, MATCH(S22/$AH22, F!$O$21:$O$33,1), MATCH(E22, F!$P$20:$AB$20,1)),0) + IFERROR(Y22*INDEX(F!$P$21:$AB$33, MATCH(W22/$AH22, F!$O$21:$O$33,1), MATCH(E22, F!$P$20:$AB$20,1)),0) + IFERROR( AC22*INDEX(F!$P$21:$AB$33, MATCH(AA22/$AH22, F!$O$21:$O$33,1), MATCH(E22, F!$P$20:$AB$20,1)),)} -> 27
A23: 43784 | B23: Тяжелая | C23: ЖМ | D23: Жим лежа | E23: 1 | G23: =IF(J23<>0, IFERROR(IF( $F23=2, MROUND($AH23*J23,1), IF( OR($F23="",$F23=1), MROUND($AH23*J23,2.5), MROUND($AH23*J23, 0.1))), "" ), "") -> 57.5 | H23: 3 | I23: 1 | J23: 0.6 | K23: =IF(N23<>0, IFERROR(IF( $F23=2, MROUND($AH23*N23,1), IF( OR($F23="",$F23=1), MROUND($AH23*N23,2.5), MROUND($AH23*N23, 0.1))), "" ), "") -> 72.5 | L23: 3 | M23: 4 | N23: 0.75 | O23: =IF(R23<>0, IFERROR(IF( $F23=2, MROUND($AH23*R23,1), IF( OR($F23="",$F23=1), MROUND($AH23*R23,2.5), MROUND($AH23*R23, 0.1))), "" ), "") | S23: =IF(V23<>0, IFERROR(IF( $F23=2, MROUND($AH23*V23,1), IF( OR($F23="",$F23=1), MROUND($AH23*V23,2.5), MROUND($AH23*V23, 0.1))), "" ), "") | W23: =IF(Z23<>0, IFERROR(IF( $F23=2, MROUND($AH23*Z23,1), IF( OR($F23="",$F23=1), MROUND($AH23*Z23,2.5), MROUND($AH23*Z23, 0.1))), "" ), "") | AA23: =IF(AD23<>0, IFERROR(IF( $F23=2, MROUND($AH23*AD23,1), IF( OR($F23="",$F23=1), MROUND($AH23*AD23,2.5), MROUND($AH23*AD23, 0.1))), "" ), "") | AE23: =(IF(ISNUMBER(G23),G23,0)*H23*I23+IF(ISNUMBER(K23),K23,1)*L23*M23+IF(ISNUMBER(O23),O23,1)*P23*Q23+IF(ISNUMBER(S23),S23,1)*T23*U23+IF(ISNUMBER(W23),W23,1)*X23*Y23+IF(ISNUMBER(AA23),AA23,1)*AB23*AC23)*IF(ISNUMBER(F23),F23,1) -> 1042.5 | AF23: =IFERROR(AE23/AJ23,0) -> 69.5 | AG23: =IFERROR((AF23/(AH23*IF(ISNUMBER(F23),F23,1))),0) -> 0.73157895 | AH23: =AH5 -> 95 | AI23: =( IF(ISNUMBER(G23), VLOOKUP(G23/$AH23,F!$A1:$B101,2,1)*G23*$H23*$I23,0)+IF(ISNUMBER(K23), VLOOKUP(K23/$AH23,F!$A1:$B101,2,1)*K23*$L23*$M23,0)+IF(ISNUMBER(O23), VLOOKUP(O23/$AH23,F!$A1:$B101,2,1)*O23*$P23*$Q23,0)+IF(ISNUMBER(S23), VLOOKUP(S23/$AH23,F!$A1:$B101,2,1)*S23*$T23*$U23,0)+IF(ISNUMBER(W23), VLOOKUP(W23/$AH23,F!$A1:$B101,2,1)*W23*$X23*$Y23,0)+IF(ISNUMBER(AA23), VLOOKUP(AA23/$AH23,F!$A1:$B101,2,1)*AA23*$AB23*$AC23,0))*IF(ISNUMBER(F23),F23,1)*IF(ISNUMBER(E23),E23,1) -> 1225.65 | AJ23: =H23*I23+L23*M23+P23*Q23+T23*U23+X23*Y23+AB23*AC23 -> 15 | AK23: {=IFERROR(I23*INDEX(F!$P$21:$AB$33, MATCH(G23/$AH23, F!$O$21:$O$33,1), MATCH(E23, F!$P$20:$AB$20,1)), 0 ) +IFERROR( M23*INDEX(F!$P$21:$AB$33, MATCH(K23/$AH23, F!$O$21:$O$33,1), MATCH(E23, F!$P$20:$AB$20,1)),0) + IFERROR( Q23*INDEX(F!$P$21:$AB$33, MATCH(O23/$AH23, F!$O$21:$O$33,1), MATCH(E23, F!$P$20:$AB$20,1)), 0) + IFERROR( U23*INDEX(F!$P$21:$AB$33, MATCH(S23/$AH23, F!$O$21:$O$33,1), MATCH(E23, F!$P$20:$AB$20,1)),0) + IFERROR(Y23*INDEX(F!$P$21:$AB$33, MATCH(W23/$AH23, F!$O$21:$O$33,1), MATCH(E23, F!$P$20:$AB$20,1)),0) + IFERROR( AC23*INDEX(F!$P$21:$AB$33, MATCH(AA23/$AH23, F!$O$21:$O$33,1), MATCH(E23, F!$P$20:$AB$20,1)),)} -> 19
B24: Средняя | C24: ПР | D24: Присед | E24: 1.2 | G24: =IF(J24<>0, IFERROR(IF( $F24=2, MROUND($AH24*J24,1), IF( OR($F24="",$F24=1), MROUND($AH24*J24,2.5), MROUND($AH24*J24, 0.1))), "" ), "") -> 80 | H24: 4 | I24: 4 | J24: 0.6 | K24: =IF(N24<>0, IFERROR(IF( $F24=2, MROUND($AH24*N24,1), IF( OR($F24="",$F24=1), MROUND($AH24*N24,2.5), MROUND($AH24*N24, 0.1))), "" ), "") | O24: =IF(R24<>0, IFERROR(IF( $F24=2, MROUND($AH24*R24,1), IF( OR($F24="",$F24=1), MROUND($AH24*R24,2.5), MROUND($AH24*R24, 0.1))), "" ), "") | S24: =IF(V24<>0, IFERROR(IF( $F24=2, MROUND($AH24*V24,1), IF( OR($F24="",$F24=1), MROUND($AH24*V24,2.5), MROUND($AH24*V24, 0.1))), "" ), "") | W24: =IF(Z24<>0, IFERROR(IF( $F24=2, MROUND($AH24*Z24,1), IF( OR($F24="",$F24=1), MROUND($AH24*Z24,2.5), MROUND($AH24*Z24, 0.1))), "" ), "") | AA24: =IF(AD24<>0, IFERROR(IF( $F24=2, MROUND($AH24*AD24,1), IF( OR($F24="",$F24=1), MROUND($AH24*AD24,2.5), MROUND($AH24*AD24, 0.1))), "" ), "") | AE24: =(IF(ISNUMBER(G24),G24,0)*H24*I24+IF(ISNUMBER(K24),K24,1)*L24*M24+IF(ISNUMBER(O24),O24,1)*P24*Q24+IF(ISNUMBER(S24),S24,1)*T24*U24+IF(ISNUMBER(W24),W24,1)*X24*Y24+IF(ISNUMBER(AA24),AA24,1)*AB24*AC24)*IF(ISNUMBER(F24),F24,1) -> 1280 | AF24: =IFERROR(AE24/AJ24,0) -> 80 | AG24: =IFERROR((AF24/(AH24*IF(ISNUMBER(F24),F24,1))),0) -> 0.59259259 | AH24: =AH22 -> 135 | AI24: =( IF(ISNUMBER(G24), VLOOKUP(G24/$AH24,F!$A1:$B101,2,1)*G24*$H24*$I24,0)+IF(ISNUMBER(K24), VLOOKUP(K24/$AH24,F!$A1:$B101,2,1)*K24*$L24*$M24,0)+IF(ISNUMBER(O24), VLOOKUP(O24/$AH24,F!$A1:$B101,2,1)*O24*$P24*$Q24,0)+IF(ISNUMBER(S24), VLOOKUP(S24/$AH24,F!$A1:$B101,2,1)*S24*$T24*$U24,0)+IF(ISNUMBER(W24), VLOOKUP(W24/$AH24,F!$A1:$B101,2,1)*W24*$X24*$Y24,0)+IF(ISNUMBER(AA24), VLOOKUP(AA24/$AH24,F!$A1:$B101,2,1)*AA24*$AB24*$AC24,0))*IF(ISNUMBER(F24),F24,1)*IF(ISNUMBER(E24),E24,1) -> 1044.48 | AJ24: =H24*I24+L24*M24+P24*Q24+T24*U24+X24*Y24+AB24*AC24 -> 16 | AK24: {=IFERROR(I24*INDEX(F!$P$21:$AB$33, MATCH(G24/$AH24, F!$O$21:$O$33,1), MATCH(E24, F!$P$20:$AB$20,1)), 0 ) +IFERROR( M24*INDEX(F!$P$21:$AB$33, MATCH(K24/$AH24, F!$O$21:$O$33,1), MATCH(E24, F!$P$20:$AB$20,1)),0) + IFERROR( Q24*INDEX(F!$P$21:$AB$33, MATCH(O24/$AH24, F!$O$21:$O$33,1), MATCH(E24, F!$P$20:$AB$20,1)), 0) + IFERROR( U24*INDEX(F!$P$21:$AB$33, MATCH(S24/$AH24, F!$O$21:$O$33,1), MATCH(E24, F!$P$20:$AB$20,1)),0) + IFERROR(Y24*INDEX(F!$P$21:$AB$33, MATCH(W24/$AH24, F!$O$21:$O$33,1), MATCH(E24, F!$P$20:$AB$20,1)),0) + IFERROR( AC24*INDEX(F!$P$21:$AB$33, MATCH(AA24/$AH24, F!$O$21:$O$33,1), MATCH(E24, F!$P$20:$AB$20,1)),)} -> 16
B25: Тяжелая | C25: ЖМ | D25: Жим на наклонной скамье | E25: 1 | G25: =IF(J25<>0, IFERROR(IF( $F25=2, MROUND($AH25*J25,1), IF( OR($F25="",$F25=1), MROUND($AH25*J25,2.5), MROUND($AH25*J25, 0.1))), "" ), "") -> 45 | H25: 4 | I25: 1 | J25: 0.6 | K25: =IF(N25<>0, IFERROR(IF( $F25=2, MROUND($AH25*N25,1), IF( OR($F25="",$F25=1), MROUND($AH25*N25,2.5), MROUND($AH25*N25, 0.1))), "" ), "") -> 52.5 | L25: 4 | M25: 4 | N25: 0.7 | O25: =IF(R25<>0, IFERROR(IF( $F25=2, MROUND($AH25*R25,1), IF( OR($F25="",$F25=1), MROUND($AH25*R25,2.5), MROUND($AH25*R25, 0.1))), "" ), "") | S25: =IF(V25<>0, IFERROR(IF( $F25=2, MROUND($AH25*V25,1), IF( OR($F25="",$F25=1), MROUND($AH25*V25,2.5), MROUND($AH25*V25, 0.1))), "" ), "") | W25: =IF(Z25<>0, IFERROR(IF( $F25=2, MROUND($AH25*Z25,1), IF( OR($F25="",$F25=1), MROUND($AH25*Z25,2.5), MROUND($AH25*Z25, 0.1))), "" ), "") | AA25: =IF(AD25<>0, IFERROR(IF( $F25=2, MROUND($AH25*AD25,1), IF( OR($F25="",$F25=1), MROUND($AH25*AD25,2.5), MROUND($AH25*AD25, 0.1))), "" ), "") | AE25: =(IF(ISNUMBER(G25),G25,0)*H25*I25+IF(ISNUMBER(K25),K25,1)*L25*M25+IF(ISNUMBER(O25),O25,1)*P25*Q25+IF(ISNUMBER(S25),S25,1)*T25*U25+IF(ISNUMBER(W25),W25,1)*X25*Y25+IF(ISNUMBER(AA25),AA25,1)*AB25*AC25)*IF(ISNUMBER(F25),F25,1) -> 1020 | AF25: =IFERROR(AE25/AJ25,0) -> 51 | AG25: =IFERROR((AF25/(AH25*IF(ISNUMBER(F25),F25,1))),0) -> 0.67105263 | AH25: =AH23*0.8 -> 76 | AI25: =( IF(ISNUMBER(G25), VLOOKUP(G25/$AH25,F!$A1:$B101,2,1)*G25*$H25*$I25,0)+IF(ISNUMBER(K25), VLOOKUP(K25/$AH25,F!$A1:$B101,2,1)*K25*$L25*$M25,0)+IF(ISNUMBER(O25), VLOOKUP(O25/$AH25,F!$A1:$B101,2,1)*O25*$P25*$Q25,0)+IF(ISNUMBER(S25), VLOOKUP(S25/$AH25,F!$A1:$B101,2,1)*S25*$T25*$U25,0)+IF(ISNUMBER(W25), VLOOKUP(W25/$AH25,F!$A1:$B101,2,1)*W25*$X25*$Y25,0)+IF(ISNUMBER(AA25), VLOOKUP(AA25/$AH25,F!$A1:$B101,2,1)*AA25*$AB25*$AC25,0))*IF(ISNUMBER(F25),F25,1)*IF(ISNUMBER(E25),E25,1) -> 870 | AJ25: =H25*I25+L25*M25+P25*Q25+T25*U25+X25*Y25+AB25*AC25 -> 20 | AK25: {=IFERROR(I25*INDEX(F!$P$21:$AB$33, MATCH(G25/$AH25, F!$O$21:$O$33,1), MATCH(E25, F!$P$20:$AB$20,1)), 0 ) +IFERROR( M25*INDEX(F!$P$21:$AB$33, MATCH(K25/$AH25, F!$O$21:$O$33,1), MATCH(E25, F!$P$20:$AB$20,1)),0) + IFERROR( Q25*INDEX(F!$P$21:$AB$33, MATCH(O25/$AH25, F!$O$21:$O$33,1), MATCH(E25, F!$P$20:$AB$20,1)), 0) + IFERROR( U25*INDEX(F!$P$21:$AB$33, MATCH(S25/$AH25, F!$O$21:$O$33,1), MATCH(E25, F!$P$20:$AB$20,1)),0) + IFERROR(Y25*INDEX(F!$P$21:$AB$33, MATCH(W25/$AH25, F!$O$21:$O$33,1), MATCH(E25, F!$P$20:$AB$20,1)),0) + IFERROR( AC25*INDEX(F!$P$21:$AB$33, MATCH(AA25/$AH25, F!$O$21:$O$33,1), MATCH(E25, F!$P$20:$AB$20,1)),)} -> 15
B26: Средняя | C26: ОФП | D26: Бицепс стоя | E26: 0.5 | G26: =IF(J26<>0, IFERROR(IF( $F26=2, MROUND($AH26*J26,1), IF( OR($F26="",$F26=1), MROUND($AH26*J26,2.5), MROUND($AH26*J26, 0.1))), "" ), "") | H26: 5 | I26: 1 | J26: 0.5 | K26: =IF(N26<>0, IFERROR(IF( $F26=2, MROUND($AH26*N26,1), IF( OR($F26="",$F26=1), MROUND($AH26*N26,2.5), MROUND($AH26*N26, 0.1))), "" ), "") | L26: 5 | M26: 5 | N26: 0.6 | O26: =IF(R26<>0, IFERROR(IF( $F26=2, MROUND($AH26*R26,1), IF( OR($F26="",$F26=1), MROUND($AH26*R26,2.5), MROUND($AH26*R26, 0.1))), "" ), "") | S26: =IF(V26<>0, IFERROR(IF( $F26=2, MROUND($AH26*V26,1), IF( OR($F26="",$F26=1), MROUND($AH26*V26,2.5), MROUND($AH26*V26, 0.1))), "" ), "") | W26: =IF(Z26<>0, IFERROR(IF( $F26=2, MROUND($AH26*Z26,1), IF( OR($F26="",$F26=1), MROUND($AH26*Z26,2.5), MROUND($AH26*Z26, 0.1))), "" ), "") | AA26: =IF(AD26<>0, IFERROR(IF( $F26=2, MROUND($AH26*AD26,1), IF( OR($F26="",$F26=1), MROUND($AH26*AD26,2.5), MROUND($AH26*AD26, 0.1))), "" ), "") | AE26: =(IF(ISNUMBER(G26),G26,0)*H26*I26+IF(ISNUMBER(K26),K26,1)*L26*M26+IF(ISNUMBER(O26),O26,1)*P26*Q26+IF(ISNUMBER(S26),S26,1)*T26*U26+IF(ISNUMBER(W26),W26,1)*X26*Y26+IF(ISNUMBER(AA26),AA26,1)*AB26*AC26)*IF(ISNUMBER(F26),F26,1) -> 25 | AF26: =IFERROR(AE26/AJ26,0) -> 0.83333333 | AG26: =IFERROR((AF26/(AH26*IF(ISNUMBER(F26),F26,1))),0) -> 0 | AH26: . | AI26: =( IF(ISNUMBER(G26), VLOOKUP(G26/$AH26,F!$A1:$B101,2,1)*G26*$H26*$I26,0)+IF(ISNUMBER(K26), VLOOKUP(K26/$AH26,F!$A1:$B101,2,1)*K26*$L26*$M26,0)+IF(ISNUMBER(O26), VLOOKUP(O26/$AH26,F!$A1:$B101,2,1)*O26*$P26*$Q26,0)+IF(ISNUMBER(S26), VLOOKUP(S26/$AH26,F!$A1:$B101,2,1)*S26*$T26*$U26,0)+IF(ISNUMBER(W26), VLOOKUP(W26/$AH26,F!$A1:$B101,2,1)*W26*$X26*$Y26,0)+IF(ISNUMBER(AA26), VLOOKUP(AA26/$AH26,F!$A1:$B101,2,1)*AA26*$AB26*$AC26,0))*IF(ISNUMBER(F26),F26,1)*IF(ISNUMBER(E26),E26,1) -> 0 | AJ26: =H26*I26+L26*M26+P26*Q26+T26*U26+X26*Y26+AB26*AC26 -> 30 | AK26: {=IFERROR(I26*INDEX(F!$P$21:$AB$33, MATCH(G26/$AH26, F!$O$21:$O$33,1), MATCH(E26, F!$P$20:$AB$20,1)), 0 ) +IFERROR( M26*INDEX(F!$P$21:$AB$33, MATCH(K26/$AH26, F!$O$21:$O$33,1), MATCH(E26, F!$P$20:$AB$20,1)),0) + IFERROR( Q26*INDEX(F!$P$21:$AB$33, MATCH(O26/$AH26, F!$O$21:$O$33,1), MATCH(E26, F!$P$20:$AB$20,1)), 0) + IFERROR( U26*INDEX(F!$P$21:$AB$33, MATCH(S26/$AH26, F!$O$21:$O$33,1), MATCH(E26, F!$P$20:$AB$20,1)),0) + IFERROR(Y26*INDEX(F!$P$21:$AB$33, MATCH(W26/$AH26, F!$O$21:$O$33,1), MATCH(E26, F!$P$20:$AB$20,1)),0) + IFERROR( AC26*INDEX(F!$P$21:$AB$33, MATCH(AA26/$AH26, F!$O$21:$O$33,1), MATCH(E26, F!$P$20:$AB$20,1)),)} -> 0
K27: =IF(N27<>0, IFERROR(IF( $F27=2, MROUND($AH27*N27,1), IF( OR($F27="",$F27=1), MROUND($AH27*N27,2.5), MROUND($AH27*N27, 0.1))), "" ), "") | O27: =IF(R27<>0, IFERROR(IF( $F27=2, MROUND($AH27*R27,1), IF( OR($F27="",$F27=1), MROUND($AH27*R27,2.5), MROUND($AH27*R27, 0.1))), "" ), "") | S27: =IF(V27<>0, IFERROR(IF( $F27=2, MROUND($AH27*V27,1), IF( OR($F27="",$F27=1), MROUND($AH27*V27,2.5), MROUND($AH27*V27, 0.1))), "" ), "") | W27: =IF(Z27<>0, IFERROR(IF( $F27=2, MROUND($AH27*Z27,1), IF( OR($F27="",$F27=1), MROUND($AH27*Z27,2.5), MROUND($AH27*Z27, 0.1))), "" ), "") | AA27: =IF(AD27<>0, IFERROR(IF( $F27=2, MROUND($AH27*AD27,1), IF( OR($F27="",$F27=1), MROUND($AH27*AD27,2.5), MROUND($AH27*AD27, 0.1))), "" ), "") | AE27: =(IF(ISNUMBER(G27),G27,0)*H27*I27+IF(ISNUMBER(K27),K27,1)*L27*M27+IF(ISNUMBER(O27),O27,1)*P27*Q27+IF(ISNUMBER(S27),S27,1)*T27*U27+IF(ISNUMBER(W27),W27,1)*X27*Y27+IF(ISNUMBER(AA27),AA27,1)*AB27*AC27)*IF(ISNUMBER(F27),F27,1) -> 0 | AF27: =IFERROR(AE27/AJ27,0) -> 0 | AG27: =IFERROR((AF27/(AH27*IF(ISNUMBER(F27),F27,1))),0) -> 0 | AI27: =( IF(ISNUMBER(G27), VLOOKUP(G27/$AH27,F!$A1:$B101,2,1)*G27*$H27*$I27,0)+IF(ISNUMBER(K27), VLOOKUP(K27/$AH27,F!$A1:$B101,2,1)*K27*$L27*$M27,0)+IF(ISNUMBER(O27), VLOOKUP(O27/$AH27,F!$A1:$B101,2,1)*O27*$P27*$Q27,0)+IF(ISNUMBER(S27), VLOOKUP(S27/$AH27,F!$A1:$B101,2,1)*S27*$T27*$U27,0)+IF(ISNUMBER(W27), VLOOKUP(W27/$AH27,F!$A1:$B101,2,1)*W27*$X27*$Y27,0)+IF(ISNUMBER(AA27), VLOOKUP(AA27/$AH27,F!$A1:$B101,2,1)*AA27*$AB27*$AC27,0))*IF(ISNUMBER(F27),F27,1)*IF(ISNUMBER(E27),E27,1) -> 0 | AJ27: =H27*I27+L27*M27+P27*Q27+T27*U27+X27*Y27+AB27*AC27 -> 0 | AK27: {=IFERROR(I27*INDEX(F!$P$21:$AB$33, MATCH(G27/$AH27, F!$O$21:$O$33,1), MATCH(E27, F!$P$20:$AB$20,1)), 0 ) +IFERROR( M27*INDEX(F!$P$21:$AB$33, MATCH(K27/$AH27, F!$O$21:$O$33,1), MATCH(E27, F!$P$20:$AB$20,1)),0) + IFERROR( Q27*INDEX(F!$P$21:$AB$33, MATCH(O27/$AH27, F!$O$21:$O$33,1), MATCH(E27, F!$P$20:$AB$20,1)), 0) + IFERROR( U27*INDEX(F!$P$21:$AB$33, MATCH(S27/$AH27, F!$O$21:$O$33,1), MATCH(E27, F!$P$20:$AB$20,1)),0) + IFERROR(Y27*INDEX(F!$P$21:$AB$33, MATCH(W27/$AH27, F!$O$21:$O$33,1), MATCH(E27, F!$P$20:$AB$20,1)),0) + IFERROR( AC27*INDEX(F!$P$21:$AB$33, MATCH(AA27/$AH27, F!$O$21:$O$33,1), MATCH(E27, F!$P$20:$AB$20,1)),)} -> 0
K28: =IF(N28<>0, IFERROR(IF( $F28=2, MROUND($AH28*N28,1), IF( OR($F28="",$F28=1), MROUND($AH28*N28,2.5), MROUND($AH28*N28, 0.1))), "" ), "") | O28: =IF(R28<>0, IFERROR(IF( $F28=2, MROUND($AH28*R28,1), IF( OR($F28="",$F28=1), MROUND($AH28*R28,2.5), MROUND($AH28*R28, 0.1))), "" ), "") | S28: =IF(V28<>0, IFERROR(IF( $F28=2, MROUND($AH28*V28,1), IF( OR($F28="",$F28=1), MROUND($AH28*V28,2.5), MROUND($AH28*V28, 0.1))), "" ), "") | W28: =IF(Z28<>0, IFERROR(IF( $F28=2, MROUND($AH28*Z28,1), IF( OR($F28="",$F28=1), MROUND($AH28*Z28,2.5), MROUND($AH28*Z28, 0.1))), "" ), "") | AA28: =IF(AD28<>0, IFERROR(IF( $F28=2, MROUND($AH28*AD28,1), IF( OR($F28="",$F28=1), MROUND($AH28*AD28,2.5), MROUND($AH28*AD28, 0.1))), "" ), "") | AE28: =(IF(ISNUMBER(G28),G28,0)*H28*I28+IF(ISNUMBER(K28),K28,1)*L28*M28+IF(ISNUMBER(O28),O28,1)*P28*Q28+IF(ISNUMBER(S28),S28,1)*T28*U28+IF(ISNUMBER(W28),W28,1)*X28*Y28+IF(ISNUMBER(AA28),AA28,1)*AB28*AC28)*IF(ISNUMBER(F28),F28,1) -> 0 | AF28: =IFERROR(AE28/AJ28,0) -> 0 | AG28: =IFERROR((AF28/(AH28*IF(ISNUMBER(F28),F28,1))),0) -> 0 | AI28: =( IF(ISNUMBER(G28), VLOOKUP(G28/$AH28,F!$A1:$B101,2,1)*G28*$H28*$I28,0)+IF(ISNUMBER(K28), VLOOKUP(K28/$AH28,F!$A1:$B101,2,1)*K28*$L28*$M28,0)+IF(ISNUMBER(O28), VLOOKUP(O28/$AH28,F!$A1:$B101,2,1)*O28*$P28*$Q28,0)+IF(ISNUMBER(S28), VLOOKUP(S28/$AH28,F!$A1:$B101,2,1)*S28*$T28*$U28,0)+IF(ISNUMBER(W28), VLOOKUP(W28/$AH28,F!$A1:$B101,2,1)*W28*$X28*$Y28,0)+IF(ISNUMBER(AA28), VLOOKUP(AA28/$AH28,F!$A1:$B101,2,1)*AA28*$AB28*$AC28,0))*IF(ISNUMBER(F28),F28,1)*IF(ISNUMBER(E28),E28,1) -> 0 | AJ28: =H28*I28+L28*M28+P28*Q28+T28*U28+X28*Y28+AB28*AC28 -> 0 | AK28: {=IFERROR(I28*INDEX(F!$P$21:$AB$33, MATCH(G28/$AH28, F!$O$21:$O$33,1), MATCH(E28, F!$P$20:$AB$20,1)), 0 ) +IFERROR( M28*INDEX(F!$P$21:$AB$33, MATCH(K28/$AH28, F!$O$21:$O$33,1), MATCH(E28, F!$P$20:$AB$20,1)),0) + IFERROR( Q28*INDEX(F!$P$21:$AB$33, MATCH(O28/$AH28, F!$O$21:$O$33,1), MATCH(E28, F!$P$20:$AB$20,1)), 0) + IFERROR( U28*INDEX(F!$P$21:$AB$33, MATCH(S28/$AH28, F!$O$21:$O$33,1), MATCH(E28, F!$P$20:$AB$20,1)),0) + IFERROR(Y28*INDEX(F!$P$21:$AB$33, MATCH(W28/$AH28, F!$O$21:$O$33,1), MATCH(E28, F!$P$20:$AB$20,1)),0) + IFERROR( AC28*INDEX(F!$P$21:$AB$33, MATCH(AA28/$AH28, F!$O$21:$O$33,1), MATCH(E28, F!$P$20:$AB$20,1)),)} -> 0
G29: =IF(J29<>0, IFERROR(IF( $F29=2, MROUND($AH29*J29,1), IF( OR($F29="",$F29=1), MROUND($AH29*J29,2.5), MROUND($AH29*J29, 0.1))), "" ), "") | K29: =IF(N29<>0, IFERROR(IF( $F29=2, MROUND($AH29*N29,1), IF( OR($F29="",$F29=1), MROUND($AH29*N29,2.5), MROUND($AH29*N29, 0.1))), "" ), "") | O29: =IF(R29<>0, IFERROR(IF( $F29=2, MROUND($AH29*R29,1), IF( OR($F29="",$F29=1), MROUND($AH29*R29,2.5), MROUND($AH29*R29, 0.1))), "" ), "") | S29: =IF(V29<>0, IFERROR(IF( $F29=2, MROUND($AH29*V29,1), IF( OR($F29="",$F29=1), MROUND($AH29*V29,2.5), MROUND($AH29*V29, 0.1))), "" ), "") | W29: =IF(Z29<>0, IFERROR(IF( $F29=2, MROUND($AH29*Z29,1), IF( OR($F29="",$F29=1), MROUND($AH29*Z29,2.5), MROUND($AH29*Z29, 0.1))), "" ), "") | AA29: =IF(AD29<>0, IFERROR(IF( $F29=2, MROUND($AH29*AD29,1), IF( OR($F29="",$F29=1), MROUND($AH29*AD29,2.5), MROUND($AH29*AD29, 0.1))), "" ), "") | AE29: =(IF(ISNUMBER(G29),G29,0)*H29*I29+IF(ISNUMBER(K29),K29,1)*L29*M29+IF(ISNUMBER(O29),O29,1)*P29*Q29+IF(ISNUMBER(S29),S29,1)*T29*U29+IF(ISNUMBER(W29),W29,1)*X29*Y29+IF(ISNUMBER(AA29),AA29,1)*AB29*AC29)*IF(ISNUMBER(F29),F29,1) -> 0 | AF29: =IFERROR(AE29/AJ29,0) -> 0 | AG29: =IFERROR((AF29/(AH29*IF(ISNUMBER(F29),F29,1))),0) -> 0 | AI29: =( IF(ISNUMBER(G29), VLOOKUP(G29/$AH29,F!$A1:$B101,2,1)*G29*$H29*$I29,0)+IF(ISNUMBER(K29), VLOOKUP(K29/$AH29,F!$A1:$B101,2,1)*K29*$L29*$M29,0)+IF(ISNUMBER(O29), VLOOKUP(O29/$AH29,F!$A1:$B101,2,1)*O29*$P29*$Q29,0)+IF(ISNUMBER(S29), VLOOKUP(S29/$AH29,F!$A1:$B101,2,1)*S29*$T29*$U29,0)+IF(ISNUMBER(W29), VLOOKUP(W29/$AH29,F!$A1:$B101,2,1)*W29*$X29*$Y29,0)+IF(ISNUMBER(AA29), VLOOKUP(AA29/$AH29,F!$A1:$B101,2,1)*AA29*$AB29*$AC29,0))*IF(ISNUMBER(F29),F29,1)*IF(ISNUMBER(E29),E29,1) -> 0 | AJ29: =H29*I29+L29*M29+P29*Q29+T29*U29+X29*Y29+AB29*AC29 -> 0 | AK29: {=IFERROR(I29*INDEX(F!$P$21:$AB$33, MATCH(G29/$AH29, F!$O$21:$O$33,1), MATCH(E29, F!$P$20:$AB$20,1)), 0 ) +IFERROR( M29*INDEX(F!$P$21:$AB$33, MATCH(K29/$AH29, F!$O$21:$O$33,1), MATCH(E29, F!$P$20:$AB$20,1)),0) + IFERROR( Q29*INDEX(F!$P$21:$AB$33, MATCH(O29/$AH29, F!$O$21:$O$33,1), MATCH(E29, F!$P$20:$AB$20,1)), 0) + IFERROR( U29*INDEX(F!$P$21:$AB$33, MATCH(S29/$AH29, F!$O$21:$O$33,1), MATCH(E29, F!$P$20:$AB$20,1)),0) + IFERROR(Y29*INDEX(F!$P$21:$AB$33, MATCH(W29/$AH29, F!$O$21:$O$33,1), MATCH(E29, F!$P$20:$AB$20,1)),0) + IFERROR( AC29*INDEX(F!$P$21:$AB$33, MATCH(AA29/$AH29, F!$O$21:$O$33,1), MATCH(E29, F!$P$20:$AB$20,1)),)} -> 0
